13-02-2023 01:23:13 AM INFO [asyncio.py:62 serve()] [Started server process [24664]]
13-02-2023 01:23:13 AM INFO [on.py:26 startup()] [Waiting for application startup.]
13-02-2023 01:23:13 AM INFO [on.py:38 startup()] [Application startup complete.]
13-02-2023 01:23:19 AM INFO [admin.py:31 admin_register()] [INSERT INTO `admin` VALUES (NULL, 'example@abc.mm', '8191515109', 'b'$2b$12$WyKGD5M.WuIZdJS2rclVpOxdvh15hhqsn9p287c.ZPGL5PcOpGLoG'', '2023-02-13 01:23:19.248751', 'primary_account', 'active');]
13-02-2023 01:23:19 AM ERROR [SqlClient.py:43 INSERT()] [(1064, "You have an error in your SQL syntax; check the manual that corresponds to your MySQL server version for the right syntax to use near '$2b$12$WyKGD5M.WuIZdJS2rclVpOxdvh15hhqsn9p287c.ZPGL5PcOpGLoG'', '2023-02-13 01:2' at line 1")]
13-02-2023 01:23:19 AM ERROR [admin.py:36 admin_register()] [Admin register - '(1064, "You have an error in your SQL syntax; check the manual that corresponds to your MySQL server version for the right syntax to use near '$2b$12$WyKGD5M.WuIZdJS2rclVpOxdvh15hhqsn9p287c.ZPGL5PcOpGLoG'', '2023-02-13 01:2' at line 1")']
13-02-2023 01:24:04 AM INFO [asyncio.py:62 serve()] [Started server process [5400]]
13-02-2023 01:24:04 AM INFO [on.py:26 startup()] [Waiting for application startup.]
13-02-2023 01:24:04 AM INFO [on.py:38 startup()] [Application startup complete.]
13-02-2023 01:24:30 AM INFO [asyncio.py:62 serve()] [Started server process [23588]]
13-02-2023 01:24:30 AM INFO [on.py:26 startup()] [Waiting for application startup.]
13-02-2023 01:24:30 AM INFO [on.py:38 startup()] [Application startup complete.]
13-02-2023 01:24:31 AM ERROR [h11_impl.py:397 run_asgi()] [Exception in ASGI application
]
Traceback (most recent call last):
  File "C:\Users\Sayed\brickred\lcd\venv\lib\site-packages\uvicorn\protocols\http\h11_impl.py", line 394, in run_asgi
    result = await app(self.scope, self.receive, self.send)
  File "C:\Users\Sayed\brickred\lcd\venv\lib\site-packages\uvicorn\middleware\proxy_headers.py", line 45, in __call__
    return await self.app(scope, receive, send)
  File "C:\Users\Sayed\brickred\lcd\venv\lib\site-packages\fastapi\applications.py", line 190, in __call__
    await super().__call__(scope, receive, send)
  File "C:\Users\Sayed\brickred\lcd\venv\lib\site-packages\starlette\applications.py", line 111, in __call__
    await self.middleware_stack(scope, receive, send)
  File "C:\Users\Sayed\brickred\lcd\venv\lib\site-packages\starlette\middleware\errors.py", line 181, in __call__
    raise exc from None
  File "C:\Users\Sayed\brickred\lcd\venv\lib\site-packages\starlette\middleware\errors.py", line 159, in __call__
    await self.app(scope, receive, _send)
  File "C:\Users\Sayed\brickred\lcd\venv\lib\site-packages\starlette\middleware\cors.py", line 86, in __call__
    await self.simple_response(scope, receive, send, request_headers=headers)
  File "C:\Users\Sayed\brickred\lcd\venv\lib\site-packages\starlette\middleware\cors.py", line 142, in simple_response
    await self.app(scope, receive, send)
  File "C:\Users\Sayed\brickred\lcd\venv\lib\site-packages\starlette\exceptions.py", line 82, in __call__
    raise exc from None
  File "C:\Users\Sayed\brickred\lcd\venv\lib\site-packages\starlette\exceptions.py", line 71, in __call__
    await self.app(scope, receive, sender)
  File "C:\Users\Sayed\brickred\lcd\venv\lib\site-packages\starlette\routing.py", line 566, in __call__
    await route.handle(scope, receive, send)
  File "C:\Users\Sayed\brickred\lcd\venv\lib\site-packages\starlette\routing.py", line 227, in handle
    await self.app(scope, receive, send)
  File "C:\Users\Sayed\brickred\lcd\venv\lib\site-packages\starlette\routing.py", line 41, in app
    response = await func(request)
  File "C:\Users\Sayed\brickred\lcd\venv\lib\site-packages\fastapi\routing.py", line 188, in app
    raw_response = await run_endpoint_function(
  File "C:\Users\Sayed\brickred\lcd\venv\lib\site-packages\fastapi\routing.py", line 135, in run_endpoint_function
    return await dependant.call(**values)
  File "D:\projects\rj\p1-sms\.\app\api\v1\endpoints\admin.py", line 28, in admin_register
    password = hash_password(data_obj.password)
  File "D:\projects\rj\p1-sms\.\app\utilities\common.py", line 7, in hash_password
    return hashed_password.encode('utf-8')
AttributeError: 'bytes' object has no attribute 'encode'
13-02-2023 01:24:59 AM INFO [asyncio.py:62 serve()] [Started server process [22944]]
13-02-2023 01:24:59 AM INFO [on.py:26 startup()] [Waiting for application startup.]
13-02-2023 01:24:59 AM INFO [on.py:38 startup()] [Application startup complete.]
13-02-2023 01:25:02 AM ERROR [h11_impl.py:397 run_asgi()] [Exception in ASGI application
]
Traceback (most recent call last):
  File "C:\Users\Sayed\brickred\lcd\venv\lib\site-packages\uvicorn\protocols\http\h11_impl.py", line 394, in run_asgi
    result = await app(self.scope, self.receive, self.send)
  File "C:\Users\Sayed\brickred\lcd\venv\lib\site-packages\uvicorn\middleware\proxy_headers.py", line 45, in __call__
    return await self.app(scope, receive, send)
  File "C:\Users\Sayed\brickred\lcd\venv\lib\site-packages\fastapi\applications.py", line 190, in __call__
    await super().__call__(scope, receive, send)
  File "C:\Users\Sayed\brickred\lcd\venv\lib\site-packages\starlette\applications.py", line 111, in __call__
    await self.middleware_stack(scope, receive, send)
  File "C:\Users\Sayed\brickred\lcd\venv\lib\site-packages\starlette\middleware\errors.py", line 181, in __call__
    raise exc from None
  File "C:\Users\Sayed\brickred\lcd\venv\lib\site-packages\starlette\middleware\errors.py", line 159, in __call__
    await self.app(scope, receive, _send)
  File "C:\Users\Sayed\brickred\lcd\venv\lib\site-packages\starlette\middleware\cors.py", line 86, in __call__
    await self.simple_response(scope, receive, send, request_headers=headers)
  File "C:\Users\Sayed\brickred\lcd\venv\lib\site-packages\starlette\middleware\cors.py", line 142, in simple_response
    await self.app(scope, receive, send)
  File "C:\Users\Sayed\brickred\lcd\venv\lib\site-packages\starlette\exceptions.py", line 82, in __call__
    raise exc from None
  File "C:\Users\Sayed\brickred\lcd\venv\lib\site-packages\starlette\exceptions.py", line 71, in __call__
    await self.app(scope, receive, sender)
  File "C:\Users\Sayed\brickred\lcd\venv\lib\site-packages\starlette\routing.py", line 566, in __call__
    await route.handle(scope, receive, send)
  File "C:\Users\Sayed\brickred\lcd\venv\lib\site-packages\starlette\routing.py", line 227, in handle
    await self.app(scope, receive, send)
  File "C:\Users\Sayed\brickred\lcd\venv\lib\site-packages\starlette\routing.py", line 41, in app
    response = await func(request)
  File "C:\Users\Sayed\brickred\lcd\venv\lib\site-packages\fastapi\routing.py", line 188, in app
    raw_response = await run_endpoint_function(
  File "C:\Users\Sayed\brickred\lcd\venv\lib\site-packages\fastapi\routing.py", line 135, in run_endpoint_function
    return await dependant.call(**values)
  File "D:\projects\rj\p1-sms\.\app\api\v1\endpoints\admin.py", line 28, in admin_register
    password = hash_password(data_obj.password).encode('utf-8')
AttributeError: 'bytes' object has no attribute 'encode'
13-02-2023 01:25:12 AM INFO [asyncio.py:62 serve()] [Started server process [5536]]
13-02-2023 01:25:12 AM INFO [on.py:26 startup()] [Waiting for application startup.]
13-02-2023 01:25:12 AM INFO [on.py:38 startup()] [Application startup complete.]
13-02-2023 01:25:13 AM ERROR [h11_impl.py:397 run_asgi()] [Exception in ASGI application
]
Traceback (most recent call last):
  File "C:\Users\Sayed\brickred\lcd\venv\lib\site-packages\uvicorn\protocols\http\h11_impl.py", line 394, in run_asgi
    result = await app(self.scope, self.receive, self.send)
  File "C:\Users\Sayed\brickred\lcd\venv\lib\site-packages\uvicorn\middleware\proxy_headers.py", line 45, in __call__
    return await self.app(scope, receive, send)
  File "C:\Users\Sayed\brickred\lcd\venv\lib\site-packages\fastapi\applications.py", line 190, in __call__
    await super().__call__(scope, receive, send)
  File "C:\Users\Sayed\brickred\lcd\venv\lib\site-packages\starlette\applications.py", line 111, in __call__
    await self.middleware_stack(scope, receive, send)
  File "C:\Users\Sayed\brickred\lcd\venv\lib\site-packages\starlette\middleware\errors.py", line 181, in __call__
    raise exc from None
  File "C:\Users\Sayed\brickred\lcd\venv\lib\site-packages\starlette\middleware\errors.py", line 159, in __call__
    await self.app(scope, receive, _send)
  File "C:\Users\Sayed\brickred\lcd\venv\lib\site-packages\starlette\middleware\cors.py", line 86, in __call__
    await self.simple_response(scope, receive, send, request_headers=headers)
  File "C:\Users\Sayed\brickred\lcd\venv\lib\site-packages\starlette\middleware\cors.py", line 142, in simple_response
    await self.app(scope, receive, send)
  File "C:\Users\Sayed\brickred\lcd\venv\lib\site-packages\starlette\exceptions.py", line 82, in __call__
    raise exc from None
  File "C:\Users\Sayed\brickred\lcd\venv\lib\site-packages\starlette\exceptions.py", line 71, in __call__
    await self.app(scope, receive, sender)
  File "C:\Users\Sayed\brickred\lcd\venv\lib\site-packages\starlette\routing.py", line 566, in __call__
    await route.handle(scope, receive, send)
  File "C:\Users\Sayed\brickred\lcd\venv\lib\site-packages\starlette\routing.py", line 227, in handle
    await self.app(scope, receive, send)
  File "C:\Users\Sayed\brickred\lcd\venv\lib\site-packages\starlette\routing.py", line 41, in app
    response = await func(request)
  File "C:\Users\Sayed\brickred\lcd\venv\lib\site-packages\fastapi\routing.py", line 188, in app
    raw_response = await run_endpoint_function(
  File "C:\Users\Sayed\brickred\lcd\venv\lib\site-packages\fastapi\routing.py", line 135, in run_endpoint_function
    return await dependant.call(**values)
  File "D:\projects\rj\p1-sms\.\app\api\v1\endpoints\admin.py", line 29, in admin_register
    query = f"INSERT INTO `admin` VALUES (NULL, '{data_obj.email}', '{data_obj.phone}', '{password.encode('utf-8')}', '{datetime.datetime.now()}', 'primary_account', " \
AttributeError: 'bytes' object has no attribute 'encode'
13-02-2023 01:25:56 AM INFO [asyncio.py:62 serve()] [Started server process [22048]]
13-02-2023 01:25:56 AM INFO [on.py:26 startup()] [Waiting for application startup.]
13-02-2023 01:25:56 AM INFO [on.py:38 startup()] [Application startup complete.]
13-02-2023 01:26:03 AM INFO [asyncio.py:62 serve()] [Started server process [17584]]
13-02-2023 01:26:03 AM INFO [on.py:26 startup()] [Waiting for application startup.]
13-02-2023 01:26:03 AM INFO [on.py:38 startup()] [Application startup complete.]
13-02-2023 01:26:44 AM INFO [asyncio.py:62 serve()] [Started server process [5260]]
13-02-2023 01:26:44 AM INFO [on.py:26 startup()] [Waiting for application startup.]
13-02-2023 01:26:44 AM INFO [on.py:38 startup()] [Application startup complete.]
13-02-2023 01:26:45 AM INFO [admin.py:31 admin_register()] [INSERT INTO `admin` VALUES (NULL, 'example@abc.mm', '8191515109', 'b'$2b$12$NGWtrS8JdVxRP1vB88ZT4OZL6XvyJgRoeD0vkIJm/gOQ0hSitt05i'', '2023-02-13 01:26:45.086471', 'primary_account', 'active');]
13-02-2023 01:26:45 AM ERROR [SqlClient.py:43 INSERT()] [(1064, "You have an error in your SQL syntax; check the manual that corresponds to your MySQL server version for the right syntax to use near '$2b$12$NGWtrS8JdVxRP1vB88ZT4OZL6XvyJgRoeD0vkIJm/gOQ0hSitt05i'', '2023-02-13 01:2' at line 1")]
13-02-2023 01:26:45 AM ERROR [admin.py:37 admin_register()] [Admin register - '(1064, "You have an error in your SQL syntax; check the manual that corresponds to your MySQL server version for the right syntax to use near '$2b$12$NGWtrS8JdVxRP1vB88ZT4OZL6XvyJgRoeD0vkIJm/gOQ0hSitt05i'', '2023-02-13 01:2' at line 1")']
13-02-2023 01:29:07 AM ERROR [h11_impl.py:397 run_asgi()] [Exception in ASGI application
]
Traceback (most recent call last):
  File "C:\Users\Sayed\brickred\lcd\venv\lib\site-packages\uvicorn\protocols\http\h11_impl.py", line 394, in run_asgi
    result = await app(self.scope, self.receive, self.send)
  File "C:\Users\Sayed\brickred\lcd\venv\lib\site-packages\uvicorn\middleware\proxy_headers.py", line 45, in __call__
    return await self.app(scope, receive, send)
  File "C:\Users\Sayed\brickred\lcd\venv\lib\site-packages\fastapi\applications.py", line 190, in __call__
    await super().__call__(scope, receive, send)
  File "C:\Users\Sayed\brickred\lcd\venv\lib\site-packages\starlette\applications.py", line 111, in __call__
    await self.middleware_stack(scope, receive, send)
  File "C:\Users\Sayed\brickred\lcd\venv\lib\site-packages\starlette\middleware\errors.py", line 181, in __call__
    raise exc from None
  File "C:\Users\Sayed\brickred\lcd\venv\lib\site-packages\starlette\middleware\errors.py", line 159, in __call__
    await self.app(scope, receive, _send)
  File "C:\Users\Sayed\brickred\lcd\venv\lib\site-packages\starlette\middleware\cors.py", line 86, in __call__
    await self.simple_response(scope, receive, send, request_headers=headers)
  File "C:\Users\Sayed\brickred\lcd\venv\lib\site-packages\starlette\middleware\cors.py", line 142, in simple_response
    await self.app(scope, receive, send)
  File "C:\Users\Sayed\brickred\lcd\venv\lib\site-packages\starlette\exceptions.py", line 82, in __call__
    raise exc from None
  File "C:\Users\Sayed\brickred\lcd\venv\lib\site-packages\starlette\exceptions.py", line 71, in __call__
    await self.app(scope, receive, sender)
  File "C:\Users\Sayed\brickred\lcd\venv\lib\site-packages\starlette\routing.py", line 566, in __call__
    await route.handle(scope, receive, send)
  File "C:\Users\Sayed\brickred\lcd\venv\lib\site-packages\starlette\routing.py", line 227, in handle
    await self.app(scope, receive, send)
  File "C:\Users\Sayed\brickred\lcd\venv\lib\site-packages\starlette\routing.py", line 41, in app
    response = await func(request)
  File "C:\Users\Sayed\brickred\lcd\venv\lib\site-packages\fastapi\routing.py", line 188, in app
    raw_response = await run_endpoint_function(
  File "C:\Users\Sayed\brickred\lcd\venv\lib\site-packages\fastapi\routing.py", line 135, in run_endpoint_function
    return await dependant.call(**values)
  File "D:\projects\rj\p1-sms\.\app\api\v1\endpoints\common.py", line 33, in login
    if not validate_hashed_password(data_obj.password, password):
  File "D:\projects\rj\p1-sms\.\app\utilities\common.py", line 12, in validate_hashed_password
    return bcrypt.checkpw(password.encode('utf-8'), hashed_password.encode('utf-8'))
  File "C:\Users\Sayed\brickred\lcd\venv\lib\site-packages\bcrypt\__init__.py", line 127, in checkpw
    ret = hashpw(password, hashed_password)
  File "C:\Users\Sayed\brickred\lcd\venv\lib\site-packages\bcrypt\__init__.py", line 105, in hashpw
    raise ValueError("Invalid salt")
ValueError: Invalid salt
13-02-2023 01:32:03 AM INFO [asyncio.py:62 serve()] [Started server process [23888]]
13-02-2023 01:32:03 AM INFO [on.py:26 startup()] [Waiting for application startup.]
13-02-2023 01:32:03 AM INFO [on.py:38 startup()] [Application startup complete.]
13-02-2023 01:32:50 AM INFO [admin.py:31 admin_register()] [INSERT INTO `admin` VALUES (NULL, 'exple@abc.mm', '8115109', '$2b$12$Ij16PRXWlGPCZ52Q1iCgxOr5FMCZI7QT.X2GTz9bKzioWluspHZB2', '2023-02-13 01:32:50.903428', 'primary_account', 'active');]
13-02-2023 01:32:50 AM INFO [SqlClient.py:41 INSERT()] [Data inserted to db]
13-02-2023 01:33:17 AM ERROR [common.py:36 login()] [Login failed - Wrong password]
13-02-2023 01:33:22 AM WARNING [common.py:27 login()] [Login failed - 'No account found']
13-02-2023 01:33:30 AM WARNING [common.py:27 login()] [Login failed - 'No account found']
13-02-2023 01:33:36 AM ERROR [common.py:36 login()] [Login failed - Wrong password]
13-02-2023 01:33:48 AM WARNING [common.py:27 login()] [Login failed - 'No account found']
13-02-2023 01:35:06 AM INFO [asyncio.py:62 serve()] [Started server process [26392]]
13-02-2023 01:35:06 AM INFO [on.py:26 startup()] [Waiting for application startup.]
13-02-2023 01:35:06 AM INFO [on.py:38 startup()] [Application startup complete.]
13-02-2023 01:35:58 AM INFO [asyncio.py:62 serve()] [Started server process [10252]]
13-02-2023 01:35:58 AM INFO [on.py:26 startup()] [Waiting for application startup.]
13-02-2023 01:35:58 AM INFO [on.py:38 startup()] [Application startup complete.]
13-02-2023 01:36:15 AM INFO [admin.py:31 admin_register()] [INSERT INTO `admin` VALUES (NULL, 'exple@abc.mm', '8115109', '$2b$12$GqfSDYMco/QR5t74BcKCr.8XTnS1HlET6ZHz5k5ef8HJzfTYLas5m', '2023-02-13 01:36:15.188379', 'primary_account', 'active');]
13-02-2023 01:36:15 AM ERROR [SqlClient.py:43 INSERT()] [(1062, "Duplicate entry 'exple@abc.mm' for key 'admin.email'")]
13-02-2023 01:36:15 AM ERROR [admin.py:36 admin_register()] [Admin register - '(1062, "Duplicate entry 'exple@abc.mm' for key 'admin.email'")']
13-02-2023 01:36:42 AM INFO [asyncio.py:62 serve()] [Started server process [25680]]
13-02-2023 01:36:42 AM INFO [on.py:26 startup()] [Waiting for application startup.]
13-02-2023 01:36:42 AM INFO [on.py:38 startup()] [Application startup complete.]
13-02-2023 01:37:17 AM INFO [asyncio.py:62 serve()] [Started server process [17032]]
13-02-2023 01:37:17 AM INFO [on.py:26 startup()] [Waiting for application startup.]
13-02-2023 01:37:17 AM INFO [on.py:38 startup()] [Application startup complete.]
13-02-2023 01:39:26 AM INFO [asyncio.py:62 serve()] [Started server process [24476]]
13-02-2023 01:39:26 AM INFO [on.py:26 startup()] [Waiting for application startup.]
13-02-2023 01:39:26 AM INFO [on.py:38 startup()] [Application startup complete.]
13-02-2023 01:39:30 AM INFO [asyncio.py:62 serve()] [Started server process [25852]]
13-02-2023 01:39:30 AM INFO [on.py:26 startup()] [Waiting for application startup.]
13-02-2023 01:39:30 AM INFO [on.py:38 startup()] [Application startup complete.]
13-02-2023 01:41:33 AM INFO [admin.py:32 admin_register()] [INSERT INTO `admin` VALUES (NULL, 'sayed@gmail.com', '1234567890', '$2b$12$rOY8xqdr8T/77sE/.2HkwerviTLeSVPQh3ShjW9RZyAGT583wpuQe', '2023-02-13 01:41:33.642095', 'primary_account', 'active');]
13-02-2023 01:41:33 AM INFO [SqlClient.py:41 INSERT()] [Data inserted to db]
13-02-2023 01:41:50 AM WARNING [common.py:27 login()] [Login failed - 'No account found']
13-02-2023 01:44:23 AM INFO [asyncio.py:62 serve()] [Started server process [7144]]
13-02-2023 01:44:23 AM INFO [on.py:26 startup()] [Waiting for application startup.]
13-02-2023 01:44:23 AM INFO [on.py:38 startup()] [Application startup complete.]
13-02-2023 01:44:35 AM INFO [asyncio.py:62 serve()] [Started server process [26284]]
13-02-2023 01:44:35 AM INFO [on.py:26 startup()] [Waiting for application startup.]
13-02-2023 01:44:35 AM INFO [on.py:38 startup()] [Application startup complete.]
13-02-2023 01:44:49 AM INFO [asyncio.py:62 serve()] [Started server process [24520]]
13-02-2023 01:44:49 AM INFO [on.py:26 startup()] [Waiting for application startup.]
13-02-2023 01:44:49 AM INFO [on.py:38 startup()] [Application startup complete.]
13-02-2023 01:45:27 AM INFO [asyncio.py:62 serve()] [Started server process [3040]]
13-02-2023 01:45:27 AM INFO [on.py:26 startup()] [Waiting for application startup.]
13-02-2023 01:45:27 AM INFO [on.py:38 startup()] [Application startup complete.]
13-02-2023 01:45:28 AM ERROR [h11_impl.py:397 run_asgi()] [Exception in ASGI application
]
Traceback (most recent call last):
  File "C:\Users\Sayed\brickred\lcd\venv\lib\site-packages\uvicorn\protocols\http\h11_impl.py", line 394, in run_asgi
    result = await app(self.scope, self.receive, self.send)
  File "C:\Users\Sayed\brickred\lcd\venv\lib\site-packages\uvicorn\middleware\proxy_headers.py", line 45, in __call__
    return await self.app(scope, receive, send)
  File "C:\Users\Sayed\brickred\lcd\venv\lib\site-packages\fastapi\applications.py", line 190, in __call__
    await super().__call__(scope, receive, send)
  File "C:\Users\Sayed\brickred\lcd\venv\lib\site-packages\starlette\applications.py", line 111, in __call__
    await self.middleware_stack(scope, receive, send)
  File "C:\Users\Sayed\brickred\lcd\venv\lib\site-packages\starlette\middleware\errors.py", line 181, in __call__
    raise exc from None
  File "C:\Users\Sayed\brickred\lcd\venv\lib\site-packages\starlette\middleware\errors.py", line 159, in __call__
    await self.app(scope, receive, _send)
  File "C:\Users\Sayed\brickred\lcd\venv\lib\site-packages\starlette\middleware\cors.py", line 78, in __call__
    await self.app(scope, receive, send)
  File "C:\Users\Sayed\brickred\lcd\venv\lib\site-packages\starlette\exceptions.py", line 82, in __call__
    raise exc from None
  File "C:\Users\Sayed\brickred\lcd\venv\lib\site-packages\starlette\exceptions.py", line 71, in __call__
    await self.app(scope, receive, sender)
  File "C:\Users\Sayed\brickred\lcd\venv\lib\site-packages\starlette\routing.py", line 566, in __call__
    await route.handle(scope, receive, send)
  File "C:\Users\Sayed\brickred\lcd\venv\lib\site-packages\starlette\routing.py", line 227, in handle
    await self.app(scope, receive, send)
  File "C:\Users\Sayed\brickred\lcd\venv\lib\site-packages\starlette\routing.py", line 41, in app
    response = await func(request)
  File "C:\Users\Sayed\brickred\lcd\venv\lib\site-packages\fastapi\routing.py", line 188, in app
    raw_response = await run_endpoint_function(
  File "C:\Users\Sayed\brickred\lcd\venv\lib\site-packages\fastapi\routing.py", line 135, in run_endpoint_function
    return await dependant.call(**values)
  File "D:\projects\rj\p1-sms\.\app\api\v1\endpoints\admin.py", line 47, in session_test
    print(await request.json())
  File "C:\Users\Sayed\brickred\lcd\venv\lib\site-packages\starlette\requests.py", line 227, in json
    self._json = json.loads(body)
  File "C:\Users\Sayed\AppData\Local\Programs\Python\Python39\lib\json\__init__.py", line 346, in loads
    return _default_decoder.decode(s)
  File "C:\Users\Sayed\AppData\Local\Programs\Python\Python39\lib\json\decoder.py", line 337, in decode
    obj, end = self.raw_decode(s, idx=_w(s, 0).end())
  File "C:\Users\Sayed\AppData\Local\Programs\Python\Python39\lib\json\decoder.py", line 355, in raw_decode
    raise JSONDecodeError("Expecting value", s, err.value) from None
json.decoder.JSONDecodeError: Expecting value: line 1 column 1 (char 0)
13-02-2023 01:45:50 AM INFO [asyncio.py:62 serve()] [Started server process [20776]]
13-02-2023 01:45:50 AM INFO [on.py:26 startup()] [Waiting for application startup.]
13-02-2023 01:45:50 AM INFO [on.py:38 startup()] [Application startup complete.]
13-02-2023 01:45:52 AM ERROR [h11_impl.py:397 run_asgi()] [Exception in ASGI application
]
Traceback (most recent call last):
  File "C:\Users\Sayed\brickred\lcd\venv\lib\site-packages\uvicorn\protocols\http\h11_impl.py", line 394, in run_asgi
    result = await app(self.scope, self.receive, self.send)
  File "C:\Users\Sayed\brickred\lcd\venv\lib\site-packages\uvicorn\middleware\proxy_headers.py", line 45, in __call__
    return await self.app(scope, receive, send)
  File "C:\Users\Sayed\brickred\lcd\venv\lib\site-packages\fastapi\applications.py", line 190, in __call__
    await super().__call__(scope, receive, send)
  File "C:\Users\Sayed\brickred\lcd\venv\lib\site-packages\starlette\applications.py", line 111, in __call__
    await self.middleware_stack(scope, receive, send)
  File "C:\Users\Sayed\brickred\lcd\venv\lib\site-packages\starlette\middleware\errors.py", line 181, in __call__
    raise exc from None
  File "C:\Users\Sayed\brickred\lcd\venv\lib\site-packages\starlette\middleware\errors.py", line 159, in __call__
    await self.app(scope, receive, _send)
  File "C:\Users\Sayed\brickred\lcd\venv\lib\site-packages\starlette\middleware\cors.py", line 78, in __call__
    await self.app(scope, receive, send)
  File "C:\Users\Sayed\brickred\lcd\venv\lib\site-packages\starlette\exceptions.py", line 82, in __call__
    raise exc from None
  File "C:\Users\Sayed\brickred\lcd\venv\lib\site-packages\starlette\exceptions.py", line 71, in __call__
    await self.app(scope, receive, sender)
  File "C:\Users\Sayed\brickred\lcd\venv\lib\site-packages\starlette\routing.py", line 566, in __call__
    await route.handle(scope, receive, send)
  File "C:\Users\Sayed\brickred\lcd\venv\lib\site-packages\starlette\routing.py", line 227, in handle
    await self.app(scope, receive, send)
  File "C:\Users\Sayed\brickred\lcd\venv\lib\site-packages\starlette\routing.py", line 41, in app
    response = await func(request)
  File "C:\Users\Sayed\brickred\lcd\venv\lib\site-packages\fastapi\routing.py", line 188, in app
    raw_response = await run_endpoint_function(
  File "C:\Users\Sayed\brickred\lcd\venv\lib\site-packages\fastapi\routing.py", line 135, in run_endpoint_function
    return await dependant.call(**values)
  File "D:\projects\rj\p1-sms\.\app\api\v1\endpoints\admin.py", line 47, in session_test
    body = await request.json()
  File "C:\Users\Sayed\brickred\lcd\venv\lib\site-packages\starlette\requests.py", line 227, in json
    self._json = json.loads(body)
  File "C:\Users\Sayed\AppData\Local\Programs\Python\Python39\lib\json\__init__.py", line 346, in loads
    return _default_decoder.decode(s)
  File "C:\Users\Sayed\AppData\Local\Programs\Python\Python39\lib\json\decoder.py", line 337, in decode
    obj, end = self.raw_decode(s, idx=_w(s, 0).end())
  File "C:\Users\Sayed\AppData\Local\Programs\Python\Python39\lib\json\decoder.py", line 355, in raw_decode
    raise JSONDecodeError("Expecting value", s, err.value) from None
json.decoder.JSONDecodeError: Expecting value: line 1 column 1 (char 0)
13-02-2023 01:49:02 AM INFO [asyncio.py:62 serve()] [Started server process [22272]]
13-02-2023 01:49:02 AM INFO [on.py:26 startup()] [Waiting for application startup.]
13-02-2023 01:49:02 AM INFO [on.py:38 startup()] [Application startup complete.]
13-02-2023 01:53:09 AM INFO [asyncio.py:62 serve()] [Started server process [13148]]
13-02-2023 01:53:09 AM INFO [on.py:26 startup()] [Waiting for application startup.]
13-02-2023 01:53:09 AM INFO [on.py:38 startup()] [Application startup complete.]
13-02-2023 01:53:12 AM INFO [asyncio.py:62 serve()] [Started server process [21176]]
13-02-2023 01:53:12 AM INFO [on.py:26 startup()] [Waiting for application startup.]
13-02-2023 01:53:12 AM INFO [on.py:38 startup()] [Application startup complete.]
13-02-2023 01:53:23 AM INFO [asyncio.py:62 serve()] [Started server process [4476]]
13-02-2023 01:53:23 AM INFO [on.py:26 startup()] [Waiting for application startup.]
13-02-2023 01:53:23 AM INFO [on.py:38 startup()] [Application startup complete.]
13-02-2023 01:53:27 AM INFO [asyncio.py:62 serve()] [Started server process [21468]]
13-02-2023 01:53:27 AM INFO [on.py:26 startup()] [Waiting for application startup.]
13-02-2023 01:53:27 AM INFO [on.py:38 startup()] [Application startup complete.]
13-02-2023 01:54:18 AM INFO [asyncio.py:62 serve()] [Started server process [25196]]
13-02-2023 01:54:18 AM INFO [on.py:26 startup()] [Waiting for application startup.]
13-02-2023 01:54:18 AM INFO [on.py:38 startup()] [Application startup complete.]
13-02-2023 12:59:00 PM INFO [asyncio.py:62 serve()] [Started server process [4908]]
13-02-2023 12:59:00 PM INFO [on.py:26 startup()] [Waiting for application startup.]
13-02-2023 12:59:00 PM INFO [on.py:38 startup()] [Application startup complete.]
13-02-2023 01:29:14 PM INFO [asyncio.py:62 serve()] [Started server process [7324]]
13-02-2023 01:29:14 PM INFO [on.py:26 startup()] [Waiting for application startup.]
13-02-2023 01:29:14 PM INFO [on.py:38 startup()] [Application startup complete.]
13-02-2023 01:37:47 PM INFO [asyncio.py:62 serve()] [Started server process [12644]]
13-02-2023 01:37:47 PM INFO [on.py:26 startup()] [Waiting for application startup.]
13-02-2023 01:37:47 PM INFO [on.py:38 startup()] [Application startup complete.]
13-02-2023 01:38:05 PM INFO [asyncio.py:62 serve()] [Started server process [11968]]
13-02-2023 01:38:05 PM INFO [on.py:26 startup()] [Waiting for application startup.]
13-02-2023 01:38:05 PM INFO [on.py:38 startup()] [Application startup complete.]
13-02-2023 01:40:05 PM INFO [asyncio.py:62 serve()] [Started server process [10772]]
13-02-2023 01:40:05 PM INFO [on.py:26 startup()] [Waiting for application startup.]
13-02-2023 01:40:05 PM INFO [on.py:38 startup()] [Application startup complete.]
13-02-2023 01:41:23 PM INFO [asyncio.py:62 serve()] [Started server process [6808]]
13-02-2023 01:41:23 PM INFO [on.py:26 startup()] [Waiting for application startup.]
13-02-2023 01:41:23 PM INFO [on.py:38 startup()] [Application startup complete.]
13-02-2023 01:43:47 PM INFO [asyncio.py:62 serve()] [Started server process [13512]]
13-02-2023 01:43:47 PM INFO [on.py:26 startup()] [Waiting for application startup.]
13-02-2023 01:43:47 PM INFO [on.py:38 startup()] [Application startup complete.]
13-02-2023 01:43:58 PM INFO [admin.py:33 admin_register()] [INSERT INTO `admin` VALUES (NULL, 'example@abc.com', '1234567890', '$2b$12$1QrUrrZWzD.0TWJMRXqFTOekS8Vlc2vzHPeit6HvJ1Ev2iyJzi91C', '2023-02-13 13:43:58.442278', 'test@gmail.com', 'active', 'admin');]
13-02-2023 01:43:58 PM INFO [SqlClient.py:41 INSERT()] [Data inserted to db]
13-02-2023 01:43:58 PM INFO [admin.py:41 admin_register()] [Admin register success- 'example@abc.com']
13-02-2023 01:44:34 PM ERROR [h11_impl.py:397 run_asgi()] [Exception in ASGI application
]
Traceback (most recent call last):
  File "C:\Users\Sayed\brickred\lcd\venv\lib\site-packages\uvicorn\protocols\http\h11_impl.py", line 394, in run_asgi
    result = await app(self.scope, self.receive, self.send)
  File "C:\Users\Sayed\brickred\lcd\venv\lib\site-packages\uvicorn\middleware\proxy_headers.py", line 45, in __call__
    return await self.app(scope, receive, send)
  File "C:\Users\Sayed\brickred\lcd\venv\lib\site-packages\fastapi\applications.py", line 190, in __call__
    await super().__call__(scope, receive, send)
  File "C:\Users\Sayed\brickred\lcd\venv\lib\site-packages\starlette\applications.py", line 111, in __call__
    await self.middleware_stack(scope, receive, send)
  File "C:\Users\Sayed\brickred\lcd\venv\lib\site-packages\starlette\middleware\errors.py", line 181, in __call__
    raise exc from None
  File "C:\Users\Sayed\brickred\lcd\venv\lib\site-packages\starlette\middleware\errors.py", line 159, in __call__
    await self.app(scope, receive, _send)
  File "C:\Users\Sayed\brickred\lcd\venv\lib\site-packages\starlette\middleware\cors.py", line 86, in __call__
    await self.simple_response(scope, receive, send, request_headers=headers)
  File "C:\Users\Sayed\brickred\lcd\venv\lib\site-packages\starlette\middleware\cors.py", line 142, in simple_response
    await self.app(scope, receive, send)
  File "C:\Users\Sayed\brickred\lcd\venv\lib\site-packages\starlette\exceptions.py", line 82, in __call__
    raise exc from None
  File "C:\Users\Sayed\brickred\lcd\venv\lib\site-packages\starlette\exceptions.py", line 71, in __call__
    await self.app(scope, receive, sender)
  File "C:\Users\Sayed\brickred\lcd\venv\lib\site-packages\starlette\routing.py", line 566, in __call__
    await route.handle(scope, receive, send)
  File "C:\Users\Sayed\brickred\lcd\venv\lib\site-packages\starlette\routing.py", line 227, in handle
    await self.app(scope, receive, send)
  File "C:\Users\Sayed\brickred\lcd\venv\lib\site-packages\starlette\routing.py", line 41, in app
    response = await func(request)
  File "C:\Users\Sayed\brickred\lcd\venv\lib\site-packages\fastapi\routing.py", line 188, in app
    raw_response = await run_endpoint_function(
  File "C:\Users\Sayed\brickred\lcd\venv\lib\site-packages\fastapi\routing.py", line 135, in run_endpoint_function
    return await dependant.call(**values)
  File "D:\projects\rj\p1-sms\.\app\api\v1\endpoints\common.py", line 31, in login
    role = data['data'][0]['role']
KeyError: 'role'
13-02-2023 01:44:56 PM INFO [asyncio.py:62 serve()] [Started server process [4492]]
13-02-2023 01:44:56 PM INFO [on.py:26 startup()] [Waiting for application startup.]
13-02-2023 01:44:56 PM INFO [on.py:38 startup()] [Application startup complete.]
13-02-2023 01:44:56 PM ERROR [common.py:37 login()] [Login failed - Wrong password]
13-02-2023 01:47:27 PM INFO [asyncio.py:62 serve()] [Started server process [10108]]
13-02-2023 01:47:27 PM INFO [on.py:26 startup()] [Waiting for application startup.]
13-02-2023 01:47:27 PM INFO [on.py:38 startup()] [Application startup complete.]
13-02-2023 01:47:46 PM INFO [asyncio.py:62 serve()] [Started server process [8492]]
13-02-2023 01:47:46 PM INFO [on.py:26 startup()] [Waiting for application startup.]
13-02-2023 01:47:46 PM INFO [on.py:38 startup()] [Application startup complete.]
13-02-2023 01:55:00 PM INFO [asyncio.py:62 serve()] [Started server process [12976]]
13-02-2023 01:55:00 PM INFO [on.py:26 startup()] [Waiting for application startup.]
13-02-2023 01:55:00 PM INFO [on.py:38 startup()] [Application startup complete.]
13-02-2023 01:58:30 PM INFO [asyncio.py:62 serve()] [Started server process [8164]]
13-02-2023 01:58:30 PM INFO [on.py:26 startup()] [Waiting for application startup.]
13-02-2023 01:58:30 PM INFO [on.py:38 startup()] [Application startup complete.]
13-02-2023 02:00:05 PM INFO [admin.py:34 admin_register()] [INSERT INTO `admin` VALUES (NULL, '1example@abc.com', '2123456789', '$2b$12$5Rz5d8d.gCxAPMCBvevwJOOFUSM8e8VpzBHSlUA.5RAqXzpk37e7q', '2023-02-13 14:00:05.476835', 'email@email.com', 'active', 'admin');]
13-02-2023 02:00:05 PM INFO [SqlClient.py:41 INSERT()] [Data inserted to db]
13-02-2023 02:00:05 PM INFO [admin.py:42 admin_register()] [Admin register success- '1example@abc.com']
13-02-2023 02:01:16 PM INFO [admin.py:34 admin_register()] [INSERT INTO `admin` VALUES (NULL, '3example@abc.com', '3123456789', '$2b$12$pdv.moYvBUURiE6.v7J.ruaIgdYdoehKZim2plkkT1hE/mvhQ1Jje', '2023-02-13 14:01:16.077903', 'email', 'active', 'student');]
13-02-2023 02:01:16 PM INFO [SqlClient.py:41 INSERT()] [Data inserted to db]
13-02-2023 02:01:16 PM INFO [admin.py:42 admin_register()] [Admin register success- '3example@abc.com']
13-02-2023 02:03:19 PM INFO [asyncio.py:62 serve()] [Started server process [11488]]
13-02-2023 02:03:19 PM INFO [on.py:26 startup()] [Waiting for application startup.]
13-02-2023 02:03:19 PM INFO [on.py:38 startup()] [Application startup complete.]
13-02-2023 02:03:28 PM INFO [asyncio.py:62 serve()] [Started server process [11512]]
13-02-2023 02:03:28 PM INFO [on.py:26 startup()] [Waiting for application startup.]
13-02-2023 02:03:28 PM INFO [on.py:38 startup()] [Application startup complete.]
13-02-2023 02:03:40 PM ERROR [h11_impl.py:397 run_asgi()] [Exception in ASGI application
]
Traceback (most recent call last):
  File "C:\Users\Sayed\brickred\lcd\venv\lib\site-packages\uvicorn\protocols\http\h11_impl.py", line 394, in run_asgi
    result = await app(self.scope, self.receive, self.send)
  File "C:\Users\Sayed\brickred\lcd\venv\lib\site-packages\uvicorn\middleware\proxy_headers.py", line 45, in __call__
    return await self.app(scope, receive, send)
  File "C:\Users\Sayed\brickred\lcd\venv\lib\site-packages\fastapi\applications.py", line 190, in __call__
    await super().__call__(scope, receive, send)
  File "C:\Users\Sayed\brickred\lcd\venv\lib\site-packages\starlette\applications.py", line 111, in __call__
    await self.middleware_stack(scope, receive, send)
  File "C:\Users\Sayed\brickred\lcd\venv\lib\site-packages\starlette\middleware\errors.py", line 181, in __call__
    raise exc from None
  File "C:\Users\Sayed\brickred\lcd\venv\lib\site-packages\starlette\middleware\errors.py", line 159, in __call__
    await self.app(scope, receive, _send)
  File "C:\Users\Sayed\brickred\lcd\venv\lib\site-packages\starlette\middleware\cors.py", line 86, in __call__
    await self.simple_response(scope, receive, send, request_headers=headers)
  File "C:\Users\Sayed\brickred\lcd\venv\lib\site-packages\starlette\middleware\cors.py", line 142, in simple_response
    await self.app(scope, receive, send)
  File "C:\Users\Sayed\brickred\lcd\venv\lib\site-packages\starlette\exceptions.py", line 82, in __call__
    raise exc from None
  File "C:\Users\Sayed\brickred\lcd\venv\lib\site-packages\starlette\exceptions.py", line 71, in __call__
    await self.app(scope, receive, sender)
  File "C:\Users\Sayed\brickred\lcd\venv\lib\site-packages\starlette\routing.py", line 566, in __call__
    await route.handle(scope, receive, send)
  File "C:\Users\Sayed\brickred\lcd\venv\lib\site-packages\starlette\routing.py", line 227, in handle
    await self.app(scope, receive, send)
  File "C:\Users\Sayed\brickred\lcd\venv\lib\site-packages\starlette\routing.py", line 41, in app
    response = await func(request)
  File "C:\Users\Sayed\brickred\lcd\venv\lib\site-packages\fastapi\routing.py", line 188, in app
    raw_response = await run_endpoint_function(
  File "C:\Users\Sayed\brickred\lcd\venv\lib\site-packages\fastapi\routing.py", line 135, in run_endpoint_function
    return await dependant.call(**values)
  File "D:\projects\rj\p1-sms\.\app\api\v1\endpoints\admin.py", line 30, in admin_register
    registered_by = token_items['email']
KeyError: 'email'
13-02-2023 02:04:41 PM INFO [asyncio.py:62 serve()] [Started server process [11684]]
13-02-2023 02:04:41 PM INFO [on.py:26 startup()] [Waiting for application startup.]
13-02-2023 02:04:41 PM INFO [on.py:38 startup()] [Application startup complete.]
13-02-2023 02:09:14 PM INFO [asyncio.py:62 serve()] [Started server process [12044]]
13-02-2023 02:09:14 PM INFO [on.py:26 startup()] [Waiting for application startup.]
13-02-2023 02:09:14 PM INFO [on.py:38 startup()] [Application startup complete.]
13-02-2023 02:10:03 PM ERROR [common.py:37 login()] [Login failed - Wrong password]
13-02-2023 02:10:31 PM INFO [admin.py:36 admin_register()] [INSERT INTO `admin` VALUES (NULL, 'example@559.com', '5168328182', '$2b$12$bXcq.H0WLPzob4CVCglyGe2I6YPZWnVxpal3ZCGv1Z/F0vOYBcJby', '2023-02-13 14:10:31.468156', 'example@abc.com', 'active', 'admin');]
13-02-2023 02:10:31 PM INFO [SqlClient.py:41 INSERT()] [Data inserted to db]
13-02-2023 02:10:31 PM INFO [admin.py:44 admin_register()] [Admin register success- 'example@559.com']
13-02-2023 02:15:54 PM INFO [asyncio.py:62 serve()] [Started server process [9636]]
13-02-2023 02:15:54 PM INFO [on.py:26 startup()] [Waiting for application startup.]
13-02-2023 02:15:54 PM INFO [on.py:38 startup()] [Application startup complete.]
13-02-2023 02:25:51 PM INFO [asyncio.py:62 serve()] [Started server process [1588]]
13-02-2023 02:25:51 PM INFO [on.py:26 startup()] [Waiting for application startup.]
13-02-2023 02:25:51 PM INFO [on.py:38 startup()] [Application startup complete.]
13-02-2023 02:27:04 PM INFO [asyncio.py:62 serve()] [Started server process [4624]]
13-02-2023 02:27:04 PM INFO [on.py:26 startup()] [Waiting for application startup.]
13-02-2023 02:27:04 PM INFO [on.py:38 startup()] [Application startup complete.]
13-02-2023 02:27:46 PM INFO [admin.py:39 admin_register()] [INSERT INTO `admin` VALUES (NULL, 'example@354.com', '5869548170', '$2b$12$tB/YwGBzYaYwFnMOBe2QLeJt1FHhr3IcFFIJvdwaipNslXWHbqh6K', '2023-02-13 14:27:46.537197', 'example@abc.com', 'active', 'admin');]
13-02-2023 02:27:46 PM INFO [SqlClient.py:41 INSERT()] [Data inserted to db]
13-02-2023 02:27:46 PM INFO [admin.py:47 admin_register()] [Admin register success- 'example@354.com']
13-02-2023 02:33:24 PM INFO [asyncio.py:62 serve()] [Started server process [14328]]
13-02-2023 02:33:24 PM INFO [on.py:26 startup()] [Waiting for application startup.]
13-02-2023 02:33:24 PM INFO [on.py:38 startup()] [Application startup complete.]
13-02-2023 02:33:24 PM ERROR [h11_impl.py:397 run_asgi()] [Exception in ASGI application
]
Traceback (most recent call last):
  File "C:\Users\Sayed\brickred\lcd\venv\lib\site-packages\uvicorn\protocols\http\h11_impl.py", line 394, in run_asgi
    result = await app(self.scope, self.receive, self.send)
  File "C:\Users\Sayed\brickred\lcd\venv\lib\site-packages\uvicorn\middleware\proxy_headers.py", line 45, in __call__
    return await self.app(scope, receive, send)
  File "C:\Users\Sayed\brickred\lcd\venv\lib\site-packages\fastapi\applications.py", line 190, in __call__
    await super().__call__(scope, receive, send)
  File "C:\Users\Sayed\brickred\lcd\venv\lib\site-packages\starlette\applications.py", line 111, in __call__
    await self.middleware_stack(scope, receive, send)
  File "C:\Users\Sayed\brickred\lcd\venv\lib\site-packages\starlette\middleware\errors.py", line 181, in __call__
    raise exc from None
  File "C:\Users\Sayed\brickred\lcd\venv\lib\site-packages\starlette\middleware\errors.py", line 159, in __call__
    await self.app(scope, receive, _send)
  File "C:\Users\Sayed\brickred\lcd\venv\lib\site-packages\starlette\middleware\cors.py", line 86, in __call__
    await self.simple_response(scope, receive, send, request_headers=headers)
  File "C:\Users\Sayed\brickred\lcd\venv\lib\site-packages\starlette\middleware\cors.py", line 142, in simple_response
    await self.app(scope, receive, send)
  File "C:\Users\Sayed\brickred\lcd\venv\lib\site-packages\starlette\exceptions.py", line 82, in __call__
    raise exc from None
  File "C:\Users\Sayed\brickred\lcd\venv\lib\site-packages\starlette\exceptions.py", line 71, in __call__
    await self.app(scope, receive, sender)
  File "C:\Users\Sayed\brickred\lcd\venv\lib\site-packages\starlette\routing.py", line 566, in __call__
    await route.handle(scope, receive, send)
  File "C:\Users\Sayed\brickred\lcd\venv\lib\site-packages\starlette\routing.py", line 227, in handle
    await self.app(scope, receive, send)
  File "C:\Users\Sayed\brickred\lcd\venv\lib\site-packages\starlette\routing.py", line 41, in app
    response = await func(request)
  File "C:\Users\Sayed\brickred\lcd\venv\lib\site-packages\fastapi\routing.py", line 188, in app
    raw_response = await run_endpoint_function(
  File "C:\Users\Sayed\brickred\lcd\venv\lib\site-packages\fastapi\routing.py", line 135, in run_endpoint_function
    return await dependant.call(**values)
  File "D:\projects\rj\p1-sms\.\app\api\v1\endpoints\admin.py", line 29, in admin_register
    token_items = decodeJWT(referrer.replace('Bearer ', ''))
AttributeError: 'NoneType' object has no attribute 'replace'
13-02-2023 02:33:24 PM ERROR [h11_impl.py:397 run_asgi()] [Exception in ASGI application
]
Traceback (most recent call last):
  File "C:\Users\Sayed\brickred\lcd\venv\lib\site-packages\uvicorn\protocols\http\h11_impl.py", line 394, in run_asgi
    result = await app(self.scope, self.receive, self.send)
  File "C:\Users\Sayed\brickred\lcd\venv\lib\site-packages\uvicorn\middleware\proxy_headers.py", line 45, in __call__
    return await self.app(scope, receive, send)
  File "C:\Users\Sayed\brickred\lcd\venv\lib\site-packages\fastapi\applications.py", line 190, in __call__
    await super().__call__(scope, receive, send)
  File "C:\Users\Sayed\brickred\lcd\venv\lib\site-packages\starlette\applications.py", line 111, in __call__
    await self.middleware_stack(scope, receive, send)
  File "C:\Users\Sayed\brickred\lcd\venv\lib\site-packages\starlette\middleware\errors.py", line 181, in __call__
    raise exc from None
  File "C:\Users\Sayed\brickred\lcd\venv\lib\site-packages\starlette\middleware\errors.py", line 159, in __call__
    await self.app(scope, receive, _send)
  File "C:\Users\Sayed\brickred\lcd\venv\lib\site-packages\starlette\middleware\cors.py", line 86, in __call__
    await self.simple_response(scope, receive, send, request_headers=headers)
  File "C:\Users\Sayed\brickred\lcd\venv\lib\site-packages\starlette\middleware\cors.py", line 142, in simple_response
    await self.app(scope, receive, send)
  File "C:\Users\Sayed\brickred\lcd\venv\lib\site-packages\starlette\exceptions.py", line 82, in __call__
    raise exc from None
  File "C:\Users\Sayed\brickred\lcd\venv\lib\site-packages\starlette\exceptions.py", line 71, in __call__
    await self.app(scope, receive, sender)
  File "C:\Users\Sayed\brickred\lcd\venv\lib\site-packages\starlette\routing.py", line 566, in __call__
    await route.handle(scope, receive, send)
  File "C:\Users\Sayed\brickred\lcd\venv\lib\site-packages\starlette\routing.py", line 227, in handle
    await self.app(scope, receive, send)
  File "C:\Users\Sayed\brickred\lcd\venv\lib\site-packages\starlette\routing.py", line 41, in app
    response = await func(request)
  File "C:\Users\Sayed\brickred\lcd\venv\lib\site-packages\fastapi\routing.py", line 188, in app
    raw_response = await run_endpoint_function(
  File "C:\Users\Sayed\brickred\lcd\venv\lib\site-packages\fastapi\routing.py", line 135, in run_endpoint_function
    return await dependant.call(**values)
  File "D:\projects\rj\p1-sms\.\app\api\v1\endpoints\admin.py", line 29, in admin_register
    token_items = decodeJWT(referrer.replace('Bearer ', ''))
AttributeError: 'NoneType' object has no attribute 'replace'
13-02-2023 02:36:10 PM INFO [asyncio.py:62 serve()] [Started server process [11760]]
13-02-2023 02:36:10 PM INFO [on.py:26 startup()] [Waiting for application startup.]
13-02-2023 02:36:10 PM INFO [on.py:38 startup()] [Application startup complete.]
13-02-2023 02:37:35 PM INFO [asyncio.py:62 serve()] [Started server process [6684]]
13-02-2023 02:37:35 PM INFO [on.py:26 startup()] [Waiting for application startup.]
13-02-2023 02:37:35 PM INFO [on.py:38 startup()] [Application startup complete.]
13-02-2023 02:37:39 PM INFO [admin.py:39 admin_register()] [INSERT INTO `admin` VALUES (NULL, 'e1xample@354.com', '5169548170', '$2b$12$AaORXVX/S0r1pNmQJs2M/.CPc3Pi6apHamuo2cW.DmYCD86o8iINm', '2023-02-13 14:37:39.213801', 'example@abc.com', 'active', 'admin');]
13-02-2023 02:37:39 PM INFO [SqlClient.py:41 INSERT()] [Data inserted to db]
13-02-2023 02:37:39 PM INFO [admin.py:47 admin_register()] [Admin register success- 'e1xample@354.com']
13-02-2023 02:39:42 PM INFO [asyncio.py:62 serve()] [Started server process [4696]]
13-02-2023 02:39:42 PM INFO [on.py:26 startup()] [Waiting for application startup.]
13-02-2023 02:39:42 PM INFO [on.py:38 startup()] [Application startup complete.]
13-02-2023 02:39:50 PM INFO [admin.py:39 admin_register()] [INSERT INTO `admin` VALUES (NULL, 'e1xample@354.com', '5169548170', '$2b$12$dQtB0/Z.xTK5jQUPLV/cmexAUhbc0ruAhYtaAVuqMTap96tI.nCu6', '2023-02-13 14:39:50.233983', 'example@abc.com', 'active', 'admin');]
13-02-2023 02:39:50 PM ERROR [SqlClient.py:43 INSERT()] [(1062, "Duplicate entry 'e1xample@354.com' for key 'admin.email'")]
13-02-2023 02:39:50 PM ERROR [admin.py:44 admin_register()] [Admin register - '(1062, "Duplicate entry 'e1xample@354.com' for key 'admin.email'")']
13-02-2023 02:39:50 PM INFO [admin.py:47 admin_register()] [Admin register success- 'e1xample@354.com']
13-02-2023 02:40:09 PM INFO [asyncio.py:62 serve()] [Started server process [13552]]
13-02-2023 02:40:09 PM INFO [on.py:26 startup()] [Waiting for application startup.]
13-02-2023 02:40:09 PM INFO [on.py:38 startup()] [Application startup complete.]
13-02-2023 02:41:18 PM INFO [asyncio.py:62 serve()] [Started server process [8188]]
13-02-2023 02:41:18 PM INFO [on.py:26 startup()] [Waiting for application startup.]
13-02-2023 02:41:18 PM INFO [on.py:38 startup()] [Application startup complete.]
13-02-2023 02:41:20 PM INFO [admin.py:39 admin_register()] [INSERT INTO `admin` VALUES (NULL, 'e1xample@354.com', '5169548170', '$2b$12$mbEw1wVdbUPXzm7C3SHNQ.aATMlYpCeV4lmOGB0KJDlpcMM9WhEoe', '2023-02-13 14:41:20.700990', 'example@abc.com', 'active', 'admin');]
13-02-2023 02:41:20 PM ERROR [SqlClient.py:43 INSERT()] [(1062, "Duplicate entry 'e1xample@354.com' for key 'admin.email'")]
13-02-2023 02:41:20 PM ERROR [admin.py:44 admin_register()] [Admin register - '(1062, "Duplicate entry 'e1xample@354.com' for key 'admin.email'")']
13-02-2023 02:41:20 PM INFO [admin.py:47 admin_register()] [Admin register success- 'e1xample@354.com']
13-02-2023 02:42:27 PM INFO [asyncio.py:62 serve()] [Started server process [7040]]
13-02-2023 02:42:27 PM INFO [on.py:26 startup()] [Waiting for application startup.]
13-02-2023 02:42:27 PM INFO [on.py:38 startup()] [Application startup complete.]
13-02-2023 02:42:54 PM INFO [admin.py:39 admin_register()] [INSERT INTO `admin` VALUES (NULL, 'e1xample@354.com', '5169548170', '$2b$12$nVPmhLs5MSmyQLj.ThwH2.l1cA1dz3NvZLX9QrvUQuEbEWJQkHor2', '2023-02-13 14:42:54.419715', 'example@abc.com', 'active', 'admin');]
13-02-2023 02:42:54 PM ERROR [SqlClient.py:43 INSERT()] [(1062, "Duplicate entry 'e1xample@354.com' for key 'admin.email'")]
13-02-2023 02:42:54 PM ERROR [admin.py:44 admin_register()] [Admin register - '(1062, "Duplicate entry 'e1xample@354.com' for key 'admin.email'")']
13-02-2023 02:42:54 PM INFO [admin.py:47 admin_register()] [Admin register success- 'e1xample@354.com']
13-02-2023 02:44:03 PM INFO [asyncio.py:62 serve()] [Started server process [6288]]
13-02-2023 02:44:03 PM INFO [on.py:26 startup()] [Waiting for application startup.]
13-02-2023 02:44:03 PM INFO [on.py:38 startup()] [Application startup complete.]
13-02-2023 02:44:03 PM ERROR [h11_impl.py:397 run_asgi()] [Exception in ASGI application
]
Traceback (most recent call last):
  File "C:\Users\Sayed\brickred\lcd\venv\lib\site-packages\uvicorn\protocols\http\h11_impl.py", line 394, in run_asgi
    result = await app(self.scope, self.receive, self.send)
  File "C:\Users\Sayed\brickred\lcd\venv\lib\site-packages\uvicorn\middleware\proxy_headers.py", line 45, in __call__
    return await self.app(scope, receive, send)
  File "C:\Users\Sayed\brickred\lcd\venv\lib\site-packages\fastapi\applications.py", line 190, in __call__
    await super().__call__(scope, receive, send)
  File "C:\Users\Sayed\brickred\lcd\venv\lib\site-packages\starlette\applications.py", line 111, in __call__
    await self.middleware_stack(scope, receive, send)
  File "C:\Users\Sayed\brickred\lcd\venv\lib\site-packages\starlette\middleware\errors.py", line 181, in __call__
    raise exc from None
  File "C:\Users\Sayed\brickred\lcd\venv\lib\site-packages\starlette\middleware\errors.py", line 159, in __call__
    await self.app(scope, receive, _send)
  File "C:\Users\Sayed\brickred\lcd\venv\lib\site-packages\starlette\middleware\cors.py", line 86, in __call__
    await self.simple_response(scope, receive, send, request_headers=headers)
  File "C:\Users\Sayed\brickred\lcd\venv\lib\site-packages\starlette\middleware\cors.py", line 142, in simple_response
    await self.app(scope, receive, send)
  File "C:\Users\Sayed\brickred\lcd\venv\lib\site-packages\starlette\exceptions.py", line 82, in __call__
    raise exc from None
  File "C:\Users\Sayed\brickred\lcd\venv\lib\site-packages\starlette\exceptions.py", line 71, in __call__
    await self.app(scope, receive, sender)
  File "C:\Users\Sayed\brickred\lcd\venv\lib\site-packages\starlette\routing.py", line 566, in __call__
    await route.handle(scope, receive, send)
  File "C:\Users\Sayed\brickred\lcd\venv\lib\site-packages\starlette\routing.py", line 227, in handle
    await self.app(scope, receive, send)
  File "C:\Users\Sayed\brickred\lcd\venv\lib\site-packages\starlette\routing.py", line 41, in app
    response = await func(request)
  File "C:\Users\Sayed\brickred\lcd\venv\lib\site-packages\fastapi\routing.py", line 188, in app
    raw_response = await run_endpoint_function(
  File "C:\Users\Sayed\brickred\lcd\venv\lib\site-packages\fastapi\routing.py", line 135, in run_endpoint_function
    return await dependant.call(**values)
  File "D:\projects\rj\p1-sms\.\app\api\v1\endpoints\admin.py", line 32, in admin_register
    invoked_endpoint = request.url.split('v1')[1]
AttributeError: 'URL' object has no attribute 'split'
13-02-2023 02:44:24 PM INFO [asyncio.py:62 serve()] [Started server process [11144]]
13-02-2023 02:44:24 PM INFO [on.py:26 startup()] [Waiting for application startup.]
13-02-2023 02:44:24 PM INFO [on.py:38 startup()] [Application startup complete.]
13-02-2023 02:44:25 PM ERROR [h11_impl.py:397 run_asgi()] [Exception in ASGI application
]
Traceback (most recent call last):
  File "C:\Users\Sayed\brickred\lcd\venv\lib\site-packages\uvicorn\protocols\http\h11_impl.py", line 394, in run_asgi
    result = await app(self.scope, self.receive, self.send)
  File "C:\Users\Sayed\brickred\lcd\venv\lib\site-packages\uvicorn\middleware\proxy_headers.py", line 45, in __call__
    return await self.app(scope, receive, send)
  File "C:\Users\Sayed\brickred\lcd\venv\lib\site-packages\fastapi\applications.py", line 190, in __call__
    await super().__call__(scope, receive, send)
  File "C:\Users\Sayed\brickred\lcd\venv\lib\site-packages\starlette\applications.py", line 111, in __call__
    await self.middleware_stack(scope, receive, send)
  File "C:\Users\Sayed\brickred\lcd\venv\lib\site-packages\starlette\middleware\errors.py", line 181, in __call__
    raise exc from None
  File "C:\Users\Sayed\brickred\lcd\venv\lib\site-packages\starlette\middleware\errors.py", line 159, in __call__
    await self.app(scope, receive, _send)
  File "C:\Users\Sayed\brickred\lcd\venv\lib\site-packages\starlette\middleware\cors.py", line 86, in __call__
    await self.simple_response(scope, receive, send, request_headers=headers)
  File "C:\Users\Sayed\brickred\lcd\venv\lib\site-packages\starlette\middleware\cors.py", line 142, in simple_response
    await self.app(scope, receive, send)
  File "C:\Users\Sayed\brickred\lcd\venv\lib\site-packages\starlette\exceptions.py", line 82, in __call__
    raise exc from None
  File "C:\Users\Sayed\brickred\lcd\venv\lib\site-packages\starlette\exceptions.py", line 71, in __call__
    await self.app(scope, receive, sender)
  File "C:\Users\Sayed\brickred\lcd\venv\lib\site-packages\starlette\routing.py", line 566, in __call__
    await route.handle(scope, receive, send)
  File "C:\Users\Sayed\brickred\lcd\venv\lib\site-packages\starlette\routing.py", line 227, in handle
    await self.app(scope, receive, send)
  File "C:\Users\Sayed\brickred\lcd\venv\lib\site-packages\starlette\routing.py", line 41, in app
    response = await func(request)
  File "C:\Users\Sayed\brickred\lcd\venv\lib\site-packages\fastapi\routing.py", line 188, in app
    raw_response = await run_endpoint_function(
  File "C:\Users\Sayed\brickred\lcd\venv\lib\site-packages\fastapi\routing.py", line 135, in run_endpoint_function
    return await dependant.call(**values)
  File "D:\projects\rj\p1-sms\.\app\api\v1\endpoints\admin.py", line 32, in admin_register
    invoked_endpoint = (request.url).split('v1')[1]
AttributeError: 'URL' object has no attribute 'split'
13-02-2023 02:45:37 PM INFO [asyncio.py:62 serve()] [Started server process [10728]]
13-02-2023 02:45:37 PM INFO [on.py:26 startup()] [Waiting for application startup.]
13-02-2023 02:45:37 PM INFO [on.py:38 startup()] [Application startup complete.]
13-02-2023 02:45:42 PM INFO [admin.py:40 admin_register()] [INSERT INTO `admin` VALUES (NULL, 'e1xample@354.com', '5169548170', '$2b$12$cdlWI352SHv5fMeaaHZHR.BU7ITXMip..LBUBVbVC1BhUPxk2oiAG', '2023-02-13 14:45:42.189373', 'example@abc.com', 'active', 'admin');]
13-02-2023 02:45:42 PM ERROR [SqlClient.py:43 INSERT()] [(1062, "Duplicate entry 'e1xample@354.com' for key 'admin.email'")]
13-02-2023 02:45:42 PM ERROR [admin.py:45 admin_register()] [Admin register - '(1062, "Duplicate entry 'e1xample@354.com' for key 'admin.email'")']
13-02-2023 02:45:42 PM INFO [admin.py:48 admin_register()] [Admin register success- 'e1xample@354.com']
13-02-2023 02:48:59 PM INFO [asyncio.py:62 serve()] [Started server process [8804]]
13-02-2023 02:48:59 PM INFO [on.py:26 startup()] [Waiting for application startup.]
13-02-2023 02:48:59 PM INFO [on.py:38 startup()] [Application startup complete.]
13-02-2023 02:50:38 PM INFO [asyncio.py:62 serve()] [Started server process [1356]]
13-02-2023 02:50:38 PM INFO [on.py:26 startup()] [Waiting for application startup.]
13-02-2023 02:50:38 PM INFO [on.py:38 startup()] [Application startup complete.]
13-02-2023 02:50:59 PM INFO [asyncio.py:62 serve()] [Started server process [4932]]
13-02-2023 02:50:59 PM INFO [on.py:26 startup()] [Waiting for application startup.]
13-02-2023 02:50:59 PM INFO [on.py:38 startup()] [Application startup complete.]
13-02-2023 02:51:15 PM INFO [asyncio.py:62 serve()] [Started server process [10108]]
13-02-2023 02:51:15 PM INFO [on.py:26 startup()] [Waiting for application startup.]
13-02-2023 02:51:15 PM INFO [on.py:38 startup()] [Application startup complete.]
13-02-2023 02:51:34 PM INFO [asyncio.py:62 serve()] [Started server process [1780]]
13-02-2023 02:51:34 PM INFO [on.py:26 startup()] [Waiting for application startup.]
13-02-2023 02:51:34 PM INFO [on.py:38 startup()] [Application startup complete.]
13-02-2023 02:51:34 PM INFO [admin.py:41 admin_register()] [INSERT INTO `admin` VALUES (NULL, 'e1xample@354.com', '5169548170', '$2b$12$84OYyA4d0JYlmiRI8uR1VOb7i2v4.dQAZkEX/gdLcEu3j.oF2oYsa', '2023-02-13 14:51:34.912687', 'example@abc.com', 'active', 'admin');]
13-02-2023 02:51:34 PM ERROR [SqlClient.py:43 INSERT()] [(1062, "Duplicate entry 'e1xample@354.com' for key 'admin.email'")]
13-02-2023 02:51:34 PM ERROR [admin.py:46 admin_register()] [Admin register - '(1062, "Duplicate entry 'e1xample@354.com' for key 'admin.email'")']
13-02-2023 02:51:34 PM INFO [admin.py:49 admin_register()] [Admin register success- 'e1xample@354.com']
13-02-2023 02:51:43 PM INFO [asyncio.py:62 serve()] [Started server process [12940]]
13-02-2023 02:51:43 PM INFO [on.py:26 startup()] [Waiting for application startup.]
13-02-2023 02:51:43 PM INFO [on.py:38 startup()] [Application startup complete.]
13-02-2023 02:59:33 PM INFO [asyncio.py:62 serve()] [Started server process [4700]]
13-02-2023 02:59:33 PM INFO [on.py:26 startup()] [Waiting for application startup.]
13-02-2023 02:59:33 PM INFO [on.py:38 startup()] [Application startup complete.]
13-02-2023 03:00:31 PM INFO [asyncio.py:62 serve()] [Started server process [6700]]
13-02-2023 03:00:31 PM INFO [on.py:26 startup()] [Waiting for application startup.]
13-02-2023 03:00:31 PM INFO [on.py:38 startup()] [Application startup complete.]
13-02-2023 03:01:06 PM INFO [asyncio.py:62 serve()] [Started server process [12920]]
13-02-2023 03:01:06 PM INFO [on.py:26 startup()] [Waiting for application startup.]
13-02-2023 03:01:06 PM INFO [on.py:38 startup()] [Application startup complete.]
13-02-2023 03:03:32 PM INFO [asyncio.py:62 serve()] [Started server process [11088]]
13-02-2023 03:03:32 PM INFO [on.py:26 startup()] [Waiting for application startup.]
13-02-2023 03:03:32 PM INFO [on.py:38 startup()] [Application startup complete.]
13-02-2023 03:04:20 PM INFO [asyncio.py:62 serve()] [Started server process [3860]]
13-02-2023 03:04:20 PM INFO [on.py:26 startup()] [Waiting for application startup.]
13-02-2023 03:04:20 PM INFO [on.py:38 startup()] [Application startup complete.]
13-02-2023 03:04:23 PM ERROR [h11_impl.py:397 run_asgi()] [Exception in ASGI application
]
Traceback (most recent call last):
  File "C:\Users\Sayed\brickred\lcd\venv\lib\site-packages\uvicorn\protocols\http\h11_impl.py", line 394, in run_asgi
    result = await app(self.scope, self.receive, self.send)
  File "C:\Users\Sayed\brickred\lcd\venv\lib\site-packages\uvicorn\middleware\proxy_headers.py", line 45, in __call__
    return await self.app(scope, receive, send)
  File "C:\Users\Sayed\brickred\lcd\venv\lib\site-packages\fastapi\applications.py", line 190, in __call__
    await super().__call__(scope, receive, send)
  File "C:\Users\Sayed\brickred\lcd\venv\lib\site-packages\starlette\applications.py", line 111, in __call__
    await self.middleware_stack(scope, receive, send)
  File "C:\Users\Sayed\brickred\lcd\venv\lib\site-packages\starlette\middleware\errors.py", line 181, in __call__
    raise exc from None
  File "C:\Users\Sayed\brickred\lcd\venv\lib\site-packages\starlette\middleware\errors.py", line 159, in __call__
    await self.app(scope, receive, _send)
  File "C:\Users\Sayed\brickred\lcd\venv\lib\site-packages\starlette\middleware\cors.py", line 86, in __call__
    await self.simple_response(scope, receive, send, request_headers=headers)
  File "C:\Users\Sayed\brickred\lcd\venv\lib\site-packages\starlette\middleware\cors.py", line 142, in simple_response
    await self.app(scope, receive, send)
  File "C:\Users\Sayed\brickred\lcd\venv\lib\site-packages\starlette\exceptions.py", line 82, in __call__
    raise exc from None
  File "C:\Users\Sayed\brickred\lcd\venv\lib\site-packages\starlette\exceptions.py", line 71, in __call__
    await self.app(scope, receive, sender)
  File "C:\Users\Sayed\brickred\lcd\venv\lib\site-packages\starlette\routing.py", line 566, in __call__
    await route.handle(scope, receive, send)
  File "C:\Users\Sayed\brickred\lcd\venv\lib\site-packages\starlette\routing.py", line 227, in handle
    await self.app(scope, receive, send)
  File "C:\Users\Sayed\brickred\lcd\venv\lib\site-packages\starlette\routing.py", line 41, in app
    response = await func(request)
  File "C:\Users\Sayed\brickred\lcd\venv\lib\site-packages\fastapi\routing.py", line 188, in app
    raw_response = await run_endpoint_function(
  File "C:\Users\Sayed\brickred\lcd\venv\lib\site-packages\fastapi\routing.py", line 135, in run_endpoint_function
    return await dependant.call(**values)
  File "D:\projects\rj\p1-sms\.\app\api\v1\endpoints\admin.py", line 35, in admin_register
    validate_access_privilege(registered_by,invokers_role,invoked_endpoint)
  File "D:\projects\rj\p1-sms\.\app\utilities\common.py", line 27, in validate_access_privilege
    if not data['data']:
KeyError: 'data'
13-02-2023 03:04:37 PM INFO [asyncio.py:62 serve()] [Started server process [1952]]
13-02-2023 03:04:37 PM INFO [on.py:26 startup()] [Waiting for application startup.]
13-02-2023 03:04:37 PM INFO [on.py:38 startup()] [Application startup complete.]
13-02-2023 03:04:37 PM ERROR [h11_impl.py:397 run_asgi()] [Exception in ASGI application
]
Traceback (most recent call last):
  File "C:\Users\Sayed\brickred\lcd\venv\lib\site-packages\uvicorn\protocols\http\h11_impl.py", line 394, in run_asgi
    result = await app(self.scope, self.receive, self.send)
  File "C:\Users\Sayed\brickred\lcd\venv\lib\site-packages\uvicorn\middleware\proxy_headers.py", line 45, in __call__
    return await self.app(scope, receive, send)
  File "C:\Users\Sayed\brickred\lcd\venv\lib\site-packages\fastapi\applications.py", line 190, in __call__
    await super().__call__(scope, receive, send)
  File "C:\Users\Sayed\brickred\lcd\venv\lib\site-packages\starlette\applications.py", line 111, in __call__
    await self.middleware_stack(scope, receive, send)
  File "C:\Users\Sayed\brickred\lcd\venv\lib\site-packages\starlette\middleware\errors.py", line 181, in __call__
    raise exc from None
  File "C:\Users\Sayed\brickred\lcd\venv\lib\site-packages\starlette\middleware\errors.py", line 159, in __call__
    await self.app(scope, receive, _send)
  File "C:\Users\Sayed\brickred\lcd\venv\lib\site-packages\starlette\middleware\cors.py", line 86, in __call__
    await self.simple_response(scope, receive, send, request_headers=headers)
  File "C:\Users\Sayed\brickred\lcd\venv\lib\site-packages\starlette\middleware\cors.py", line 142, in simple_response
    await self.app(scope, receive, send)
  File "C:\Users\Sayed\brickred\lcd\venv\lib\site-packages\starlette\exceptions.py", line 82, in __call__
    raise exc from None
  File "C:\Users\Sayed\brickred\lcd\venv\lib\site-packages\starlette\exceptions.py", line 71, in __call__
    await self.app(scope, receive, sender)
  File "C:\Users\Sayed\brickred\lcd\venv\lib\site-packages\starlette\routing.py", line 566, in __call__
    await route.handle(scope, receive, send)
  File "C:\Users\Sayed\brickred\lcd\venv\lib\site-packages\starlette\routing.py", line 227, in handle
    await self.app(scope, receive, send)
  File "C:\Users\Sayed\brickred\lcd\venv\lib\site-packages\starlette\routing.py", line 41, in app
    response = await func(request)
  File "C:\Users\Sayed\brickred\lcd\venv\lib\site-packages\fastapi\routing.py", line 188, in app
    raw_response = await run_endpoint_function(
  File "C:\Users\Sayed\brickred\lcd\venv\lib\site-packages\fastapi\routing.py", line 135, in run_endpoint_function
    return await dependant.call(**values)
  File "D:\projects\rj\p1-sms\.\app\api\v1\endpoints\admin.py", line 35, in admin_register
    validate_access_privilege(registered_by,invokers_role,invoked_endpoint)
  File "D:\projects\rj\p1-sms\.\app\utilities\common.py", line 28, in validate_access_privilege
    logging.warning(f"Invalid endpoint - '{data['error']}'")
KeyError: 'error'
13-02-2023 03:04:57 PM INFO [asyncio.py:62 serve()] [Started server process [8608]]
13-02-2023 03:04:57 PM INFO [on.py:26 startup()] [Waiting for application startup.]
13-02-2023 03:04:57 PM INFO [on.py:38 startup()] [Application startup complete.]
13-02-2023 03:04:58 PM ERROR [h11_impl.py:397 run_asgi()] [Exception in ASGI application
]
Traceback (most recent call last):
  File "C:\Users\Sayed\brickred\lcd\venv\lib\site-packages\uvicorn\protocols\http\h11_impl.py", line 394, in run_asgi
    result = await app(self.scope, self.receive, self.send)
  File "C:\Users\Sayed\brickred\lcd\venv\lib\site-packages\uvicorn\middleware\proxy_headers.py", line 45, in __call__
    return await self.app(scope, receive, send)
  File "C:\Users\Sayed\brickred\lcd\venv\lib\site-packages\fastapi\applications.py", line 190, in __call__
    await super().__call__(scope, receive, send)
  File "C:\Users\Sayed\brickred\lcd\venv\lib\site-packages\starlette\applications.py", line 111, in __call__
    await self.middleware_stack(scope, receive, send)
  File "C:\Users\Sayed\brickred\lcd\venv\lib\site-packages\starlette\middleware\errors.py", line 181, in __call__
    raise exc from None
  File "C:\Users\Sayed\brickred\lcd\venv\lib\site-packages\starlette\middleware\errors.py", line 159, in __call__
    await self.app(scope, receive, _send)
  File "C:\Users\Sayed\brickred\lcd\venv\lib\site-packages\starlette\middleware\cors.py", line 86, in __call__
    await self.simple_response(scope, receive, send, request_headers=headers)
  File "C:\Users\Sayed\brickred\lcd\venv\lib\site-packages\starlette\middleware\cors.py", line 142, in simple_response
    await self.app(scope, receive, send)
  File "C:\Users\Sayed\brickred\lcd\venv\lib\site-packages\starlette\exceptions.py", line 82, in __call__
    raise exc from None
  File "C:\Users\Sayed\brickred\lcd\venv\lib\site-packages\starlette\exceptions.py", line 71, in __call__
    await self.app(scope, receive, sender)
  File "C:\Users\Sayed\brickred\lcd\venv\lib\site-packages\starlette\routing.py", line 566, in __call__
    await route.handle(scope, receive, send)
  File "C:\Users\Sayed\brickred\lcd\venv\lib\site-packages\starlette\routing.py", line 227, in handle
    await self.app(scope, receive, send)
  File "C:\Users\Sayed\brickred\lcd\venv\lib\site-packages\starlette\routing.py", line 41, in app
    response = await func(request)
  File "C:\Users\Sayed\brickred\lcd\venv\lib\site-packages\fastapi\routing.py", line 188, in app
    raw_response = await run_endpoint_function(
  File "C:\Users\Sayed\brickred\lcd\venv\lib\site-packages\fastapi\routing.py", line 135, in run_endpoint_function
    return await dependant.call(**values)
  File "D:\projects\rj\p1-sms\.\app\api\v1\endpoints\admin.py", line 35, in admin_register
    validate_access_privilege(registered_by,invokers_role,invoked_endpoint)
  File "D:\projects\rj\p1-sms\.\app\utilities\common.py", line 29, in validate_access_privilege
    logging.warning(f"Invalid endpoint - '{data['error']}'")
KeyError: 'error'
13-02-2023 03:06:06 PM INFO [asyncio.py:62 serve()] [Started server process [14116]]
13-02-2023 03:06:06 PM INFO [on.py:26 startup()] [Waiting for application startup.]
13-02-2023 03:06:06 PM INFO [on.py:38 startup()] [Application startup complete.]
13-02-2023 03:06:10 PM WARNING [common.py:29 validate_access_privilege()] [Invalid endpoint]
13-02-2023 03:06:10 PM INFO [admin.py:41 admin_register()] [INSERT INTO `admin` VALUES (NULL, 'e1xample@354.com', '5169548170', '$2b$12$UhUskHrLdkchbn7ie4yI8epq6.s69om515ozfMvH5h1KvU5iN/H/q', '2023-02-13 15:06:10.379639', 'example@abc.com', 'active', 'admin');]
13-02-2023 03:06:10 PM ERROR [SqlClient.py:43 INSERT()] [(1062, "Duplicate entry 'e1xample@354.com' for key 'admin.email'")]
13-02-2023 03:06:10 PM ERROR [admin.py:46 admin_register()] [Admin register - '(1062, "Duplicate entry 'e1xample@354.com' for key 'admin.email'")']
13-02-2023 03:06:10 PM INFO [admin.py:49 admin_register()] [Admin register success- 'e1xample@354.com']
13-02-2023 03:06:43 PM INFO [asyncio.py:62 serve()] [Started server process [11760]]
13-02-2023 03:06:43 PM INFO [on.py:26 startup()] [Waiting for application startup.]
13-02-2023 03:06:43 PM INFO [on.py:38 startup()] [Application startup complete.]
13-02-2023 03:06:52 PM WARNING [common.py:30 validate_access_privilege()] [Invalid endpoint]
13-02-2023 03:06:52 PM INFO [admin.py:41 admin_register()] [INSERT INTO `admin` VALUES (NULL, 'e1xample@354.com', '5169548170', '$2b$12$ZCn8pHU6UweMlTt5tZVE2OwEOA7lInRkEyU.GEjaU9rJaSOieI2E.', '2023-02-13 15:06:52.696341', 'example@abc.com', 'active', 'admin');]
13-02-2023 03:06:52 PM ERROR [SqlClient.py:43 INSERT()] [(1062, "Duplicate entry 'e1xample@354.com' for key 'admin.email'")]
13-02-2023 03:06:52 PM ERROR [admin.py:46 admin_register()] [Admin register - '(1062, "Duplicate entry 'e1xample@354.com' for key 'admin.email'")']
13-02-2023 03:06:52 PM INFO [admin.py:49 admin_register()] [Admin register success- 'e1xample@354.com']
13-02-2023 03:07:57 PM INFO [asyncio.py:62 serve()] [Started server process [6532]]
13-02-2023 03:07:57 PM INFO [on.py:26 startup()] [Waiting for application startup.]
13-02-2023 03:07:57 PM INFO [on.py:38 startup()] [Application startup complete.]
13-02-2023 03:09:17 PM INFO [asyncio.py:62 serve()] [Started server process [14096]]
13-02-2023 03:09:17 PM INFO [on.py:26 startup()] [Waiting for application startup.]
13-02-2023 03:09:17 PM INFO [on.py:38 startup()] [Application startup complete.]
13-02-2023 03:09:28 PM INFO [admin.py:41 admin_register()] [INSERT INTO `admin` VALUES (NULL, 'e1xample@354.com', '5169548170', '$2b$12$TUJNwK.HxrLp6RtvWZHJOerI0OkkiJXml.Ce5MRr6DTNrGXYRCsou', '2023-02-13 15:09:28.556635', 'example@abc.com', 'active', 'admin');]
13-02-2023 03:09:28 PM ERROR [SqlClient.py:43 INSERT()] [(1062, "Duplicate entry 'e1xample@354.com' for key 'admin.email'")]
13-02-2023 03:09:28 PM ERROR [admin.py:46 admin_register()] [Admin register - '(1062, "Duplicate entry 'e1xample@354.com' for key 'admin.email'")']
13-02-2023 03:09:28 PM INFO [admin.py:49 admin_register()] [Admin register success- 'e1xample@354.com']
13-02-2023 03:55:55 PM INFO [asyncio.py:62 serve()] [Started server process [13096]]
13-02-2023 03:55:55 PM INFO [on.py:26 startup()] [Waiting for application startup.]
13-02-2023 03:55:55 PM INFO [on.py:38 startup()] [Application startup complete.]
13-02-2023 04:30:06 PM INFO [asyncio.py:62 serve()] [Started server process [12596]]
13-02-2023 04:30:06 PM INFO [on.py:26 startup()] [Waiting for application startup.]
13-02-2023 04:30:06 PM INFO [on.py:38 startup()] [Application startup complete.]
13-02-2023 04:37:13 PM INFO [asyncio.py:62 serve()] [Started server process [14504]]
13-02-2023 04:37:13 PM INFO [on.py:26 startup()] [Waiting for application startup.]
13-02-2023 04:37:13 PM INFO [on.py:38 startup()] [Application startup complete.]
13-02-2023 04:38:21 PM INFO [asyncio.py:62 serve()] [Started server process [5772]]
13-02-2023 04:38:21 PM INFO [on.py:26 startup()] [Waiting for application startup.]
13-02-2023 04:38:21 PM INFO [on.py:38 startup()] [Application startup complete.]
13-02-2023 04:38:45 PM INFO [asyncio.py:62 serve()] [Started server process [15340]]
13-02-2023 04:38:45 PM INFO [on.py:26 startup()] [Waiting for application startup.]
13-02-2023 04:38:45 PM INFO [on.py:38 startup()] [Application startup complete.]
13-02-2023 04:39:18 PM ERROR [h11_impl.py:397 run_asgi()] [Exception in ASGI application
]
Traceback (most recent call last):
  File "C:\Users\Sayed\brickred\lcd\venv\lib\site-packages\uvicorn\protocols\http\h11_impl.py", line 394, in run_asgi
    result = await app(self.scope, self.receive, self.send)
  File "C:\Users\Sayed\brickred\lcd\venv\lib\site-packages\uvicorn\middleware\proxy_headers.py", line 45, in __call__
    return await self.app(scope, receive, send)
  File "C:\Users\Sayed\brickred\lcd\venv\lib\site-packages\fastapi\applications.py", line 190, in __call__
    await super().__call__(scope, receive, send)
  File "C:\Users\Sayed\brickred\lcd\venv\lib\site-packages\starlette\applications.py", line 111, in __call__
    await self.middleware_stack(scope, receive, send)
  File "C:\Users\Sayed\brickred\lcd\venv\lib\site-packages\starlette\middleware\errors.py", line 181, in __call__
    raise exc from None
  File "C:\Users\Sayed\brickred\lcd\venv\lib\site-packages\starlette\middleware\errors.py", line 159, in __call__
    await self.app(scope, receive, _send)
  File "C:\Users\Sayed\brickred\lcd\venv\lib\site-packages\starlette\middleware\cors.py", line 86, in __call__
    await self.simple_response(scope, receive, send, request_headers=headers)
  File "C:\Users\Sayed\brickred\lcd\venv\lib\site-packages\starlette\middleware\cors.py", line 142, in simple_response
    await self.app(scope, receive, send)
  File "C:\Users\Sayed\brickred\lcd\venv\lib\site-packages\starlette\exceptions.py", line 82, in __call__
    raise exc from None
  File "C:\Users\Sayed\brickred\lcd\venv\lib\site-packages\starlette\exceptions.py", line 71, in __call__
    await self.app(scope, receive, sender)
  File "C:\Users\Sayed\brickred\lcd\venv\lib\site-packages\starlette\routing.py", line 566, in __call__
    await route.handle(scope, receive, send)
  File "C:\Users\Sayed\brickred\lcd\venv\lib\site-packages\starlette\routing.py", line 227, in handle
    await self.app(scope, receive, send)
  File "C:\Users\Sayed\brickred\lcd\venv\lib\site-packages\starlette\routing.py", line 41, in app
    response = await func(request)
  File "C:\Users\Sayed\brickred\lcd\venv\lib\site-packages\fastapi\routing.py", line 188, in app
    raw_response = await run_endpoint_function(
  File "C:\Users\Sayed\brickred\lcd\venv\lib\site-packages\fastapi\routing.py", line 135, in run_endpoint_function
    return await dependant.call(**values)
  File "D:\projects\rj\p1-sms\.\app\api\v1\endpoints\admin.py", line 35, in admin_register
    validate_access_privilege(registered_by,invokers_role,invoked_endpoint)
  File "D:\projects\rj\p1-sms\.\app\utilities\common.py", line 42, in validate_access_privilege
    __check_if_access_allowed(data, invoker_id, invoker_role)
  File "D:\projects\rj\p1-sms\.\app\utilities\common.py", line 23, in __check_if_access_allowed
    is_disabled = data['is_disabled']
KeyError: 'is_disabled'
13-02-2023 04:40:04 PM INFO [asyncio.py:62 serve()] [Started server process [7024]]
13-02-2023 04:40:04 PM INFO [on.py:26 startup()] [Waiting for application startup.]
13-02-2023 04:40:04 PM INFO [on.py:38 startup()] [Application startup complete.]
13-02-2023 04:40:07 PM ERROR [h11_impl.py:397 run_asgi()] [Exception in ASGI application
]
Traceback (most recent call last):
  File "C:\Users\Sayed\brickred\lcd\venv\lib\site-packages\uvicorn\protocols\http\h11_impl.py", line 394, in run_asgi
    result = await app(self.scope, self.receive, self.send)
  File "C:\Users\Sayed\brickred\lcd\venv\lib\site-packages\uvicorn\middleware\proxy_headers.py", line 45, in __call__
    return await self.app(scope, receive, send)
  File "C:\Users\Sayed\brickred\lcd\venv\lib\site-packages\fastapi\applications.py", line 190, in __call__
    await super().__call__(scope, receive, send)
  File "C:\Users\Sayed\brickred\lcd\venv\lib\site-packages\starlette\applications.py", line 111, in __call__
    await self.middleware_stack(scope, receive, send)
  File "C:\Users\Sayed\brickred\lcd\venv\lib\site-packages\starlette\middleware\errors.py", line 181, in __call__
    raise exc from None
  File "C:\Users\Sayed\brickred\lcd\venv\lib\site-packages\starlette\middleware\errors.py", line 159, in __call__
    await self.app(scope, receive, _send)
  File "C:\Users\Sayed\brickred\lcd\venv\lib\site-packages\starlette\middleware\cors.py", line 86, in __call__
    await self.simple_response(scope, receive, send, request_headers=headers)
  File "C:\Users\Sayed\brickred\lcd\venv\lib\site-packages\starlette\middleware\cors.py", line 142, in simple_response
    await self.app(scope, receive, send)
  File "C:\Users\Sayed\brickred\lcd\venv\lib\site-packages\starlette\exceptions.py", line 82, in __call__
    raise exc from None
  File "C:\Users\Sayed\brickred\lcd\venv\lib\site-packages\starlette\exceptions.py", line 71, in __call__
    await self.app(scope, receive, sender)
  File "C:\Users\Sayed\brickred\lcd\venv\lib\site-packages\starlette\routing.py", line 566, in __call__
    await route.handle(scope, receive, send)
  File "C:\Users\Sayed\brickred\lcd\venv\lib\site-packages\starlette\routing.py", line 227, in handle
    await self.app(scope, receive, send)
  File "C:\Users\Sayed\brickred\lcd\venv\lib\site-packages\starlette\routing.py", line 41, in app
    response = await func(request)
  File "C:\Users\Sayed\brickred\lcd\venv\lib\site-packages\fastapi\routing.py", line 188, in app
    raw_response = await run_endpoint_function(
  File "C:\Users\Sayed\brickred\lcd\venv\lib\site-packages\fastapi\routing.py", line 135, in run_endpoint_function
    return await dependant.call(**values)
  File "D:\projects\rj\p1-sms\.\app\api\v1\endpoints\admin.py", line 35, in admin_register
    validate_access_privilege(registered_by,invokers_role,invoked_endpoint)
  File "D:\projects\rj\p1-sms\.\app\utilities\common.py", line 43, in validate_access_privilege
    __check_if_access_allowed(data, invoker_id, invoker_role)
  File "D:\projects\rj\p1-sms\.\app\utilities\common.py", line 23, in __check_if_access_allowed
    is_disabled = data['is_disabled']
KeyError: 'is_disabled'
13-02-2023 04:41:16 PM INFO [asyncio.py:62 serve()] [Started server process [11756]]
13-02-2023 04:41:16 PM INFO [on.py:26 startup()] [Waiting for application startup.]
13-02-2023 04:41:16 PM INFO [on.py:38 startup()] [Application startup complete.]
13-02-2023 04:41:41 PM INFO [asyncio.py:62 serve()] [Started server process [14432]]
13-02-2023 04:41:41 PM INFO [on.py:26 startup()] [Waiting for application startup.]
13-02-2023 04:41:41 PM INFO [on.py:38 startup()] [Application startup complete.]
13-02-2023 04:42:02 PM INFO [asyncio.py:62 serve()] [Started server process [11088]]
13-02-2023 04:42:02 PM INFO [on.py:26 startup()] [Waiting for application startup.]
13-02-2023 04:42:02 PM INFO [on.py:38 startup()] [Application startup complete.]
13-02-2023 04:42:33 PM INFO [asyncio.py:62 serve()] [Started server process [9280]]
13-02-2023 04:42:33 PM INFO [on.py:26 startup()] [Waiting for application startup.]
13-02-2023 04:42:33 PM INFO [on.py:38 startup()] [Application startup complete.]
13-02-2023 04:42:48 PM INFO [asyncio.py:62 serve()] [Started server process [12464]]
13-02-2023 04:42:48 PM INFO [on.py:26 startup()] [Waiting for application startup.]
13-02-2023 04:42:48 PM INFO [on.py:38 startup()] [Application startup complete.]
13-02-2023 04:47:56 PM INFO [asyncio.py:62 serve()] [Started server process [12648]]
13-02-2023 04:47:56 PM INFO [on.py:26 startup()] [Waiting for application startup.]
13-02-2023 04:47:56 PM INFO [on.py:38 startup()] [Application startup complete.]
13-02-2023 04:47:56 PM ERROR [h11_impl.py:397 run_asgi()] [Exception in ASGI application
]
Traceback (most recent call last):
  File "C:\Users\Sayed\brickred\lcd\venv\lib\site-packages\uvicorn\protocols\http\h11_impl.py", line 394, in run_asgi
    result = await app(self.scope, self.receive, self.send)
  File "C:\Users\Sayed\brickred\lcd\venv\lib\site-packages\uvicorn\middleware\proxy_headers.py", line 45, in __call__
    return await self.app(scope, receive, send)
  File "C:\Users\Sayed\brickred\lcd\venv\lib\site-packages\fastapi\applications.py", line 190, in __call__
    await super().__call__(scope, receive, send)
  File "C:\Users\Sayed\brickred\lcd\venv\lib\site-packages\starlette\applications.py", line 111, in __call__
    await self.middleware_stack(scope, receive, send)
  File "C:\Users\Sayed\brickred\lcd\venv\lib\site-packages\starlette\middleware\errors.py", line 181, in __call__
    raise exc from None
  File "C:\Users\Sayed\brickred\lcd\venv\lib\site-packages\starlette\middleware\errors.py", line 159, in __call__
    await self.app(scope, receive, _send)
  File "C:\Users\Sayed\brickred\lcd\venv\lib\site-packages\starlette\middleware\cors.py", line 86, in __call__
    await self.simple_response(scope, receive, send, request_headers=headers)
  File "C:\Users\Sayed\brickred\lcd\venv\lib\site-packages\starlette\middleware\cors.py", line 142, in simple_response
    await self.app(scope, receive, send)
  File "C:\Users\Sayed\brickred\lcd\venv\lib\site-packages\starlette\exceptions.py", line 82, in __call__
    raise exc from None
  File "C:\Users\Sayed\brickred\lcd\venv\lib\site-packages\starlette\exceptions.py", line 71, in __call__
    await self.app(scope, receive, sender)
  File "C:\Users\Sayed\brickred\lcd\venv\lib\site-packages\starlette\routing.py", line 566, in __call__
    await route.handle(scope, receive, send)
  File "C:\Users\Sayed\brickred\lcd\venv\lib\site-packages\starlette\routing.py", line 227, in handle
    await self.app(scope, receive, send)
  File "C:\Users\Sayed\brickred\lcd\venv\lib\site-packages\starlette\routing.py", line 41, in app
    response = await func(request)
  File "C:\Users\Sayed\brickred\lcd\venv\lib\site-packages\fastapi\routing.py", line 188, in app
    raw_response = await run_endpoint_function(
  File "C:\Users\Sayed\brickred\lcd\venv\lib\site-packages\fastapi\routing.py", line 135, in run_endpoint_function
    return await dependant.call(**values)
  File "D:\projects\rj\p1-sms\.\app\api\v1\endpoints\admin.py", line 35, in admin_register
    validate_access_privilege(registered_by,invokers_role,invoked_endpoint)
  File "D:\projects\rj\p1-sms\.\app\utilities\common.py", line 44, in validate_access_privilege
    __check_if_access_allowed(data['data'][0], invoker_id, invoker_role)
  File "D:\projects\rj\p1-sms\.\app\utilities\common.py", line 32, in __check_if_access_allowed
    print(allowed_roles.split(','))
AttributeError: 'list' object has no attribute 'split'
13-02-2023 04:48:09 PM INFO [asyncio.py:62 serve()] [Started server process [3864]]
13-02-2023 04:48:09 PM INFO [on.py:26 startup()] [Waiting for application startup.]
13-02-2023 04:48:09 PM INFO [on.py:38 startup()] [Application startup complete.]
13-02-2023 04:48:53 PM INFO [asyncio.py:62 serve()] [Started server process [14860]]
13-02-2023 04:48:53 PM INFO [on.py:26 startup()] [Waiting for application startup.]
13-02-2023 04:48:53 PM INFO [on.py:38 startup()] [Application startup complete.]
13-02-2023 04:49:46 PM INFO [asyncio.py:62 serve()] [Started server process [13292]]
13-02-2023 04:49:46 PM INFO [on.py:26 startup()] [Waiting for application startup.]
13-02-2023 04:49:46 PM INFO [on.py:38 startup()] [Application startup complete.]
13-02-2023 04:49:48 PM INFO [admin.py:41 admin_register()] [INSERT INTO `admin` VALUES (NULL, 'e1xample@354.com', '5169548170', '$2b$12$uEjeiQPaxOSSwJSoRTiLd.PZdY1hJWcspKMg.AHgutsrnTjtD5uRC', '2023-02-13 16:49:48.230557', 'example@abc.com', 'active', 'admin');]
13-02-2023 04:49:48 PM ERROR [SqlClient.py:43 INSERT()] [(1062, "Duplicate entry 'e1xample@354.com' for key 'admin.email'")]
13-02-2023 04:49:48 PM ERROR [admin.py:46 admin_register()] [Admin register - '(1062, "Duplicate entry 'e1xample@354.com' for key 'admin.email'")']
13-02-2023 04:49:48 PM INFO [admin.py:49 admin_register()] [Admin register success- 'e1xample@354.com']
13-02-2023 04:56:05 PM INFO [asyncio.py:62 serve()] [Started server process [13012]]
13-02-2023 04:56:05 PM INFO [on.py:26 startup()] [Waiting for application startup.]
13-02-2023 04:56:05 PM INFO [on.py:38 startup()] [Application startup complete.]
13-02-2023 04:56:08 PM ERROR [h11_impl.py:397 run_asgi()] [Exception in ASGI application
]
Traceback (most recent call last):
  File "C:\Users\Sayed\brickred\lcd\venv\lib\site-packages\uvicorn\protocols\http\h11_impl.py", line 394, in run_asgi
    result = await app(self.scope, self.receive, self.send)
  File "C:\Users\Sayed\brickred\lcd\venv\lib\site-packages\uvicorn\middleware\proxy_headers.py", line 45, in __call__
    return await self.app(scope, receive, send)
  File "C:\Users\Sayed\brickred\lcd\venv\lib\site-packages\fastapi\applications.py", line 190, in __call__
    await super().__call__(scope, receive, send)
  File "C:\Users\Sayed\brickred\lcd\venv\lib\site-packages\starlette\applications.py", line 111, in __call__
    await self.middleware_stack(scope, receive, send)
  File "C:\Users\Sayed\brickred\lcd\venv\lib\site-packages\starlette\middleware\errors.py", line 181, in __call__
    raise exc from None
  File "C:\Users\Sayed\brickred\lcd\venv\lib\site-packages\starlette\middleware\errors.py", line 159, in __call__
    await self.app(scope, receive, _send)
  File "C:\Users\Sayed\brickred\lcd\venv\lib\site-packages\starlette\middleware\cors.py", line 86, in __call__
    await self.simple_response(scope, receive, send, request_headers=headers)
  File "C:\Users\Sayed\brickred\lcd\venv\lib\site-packages\starlette\middleware\cors.py", line 142, in simple_response
    await self.app(scope, receive, send)
  File "C:\Users\Sayed\brickred\lcd\venv\lib\site-packages\starlette\exceptions.py", line 82, in __call__
    raise exc from None
  File "C:\Users\Sayed\brickred\lcd\venv\lib\site-packages\starlette\exceptions.py", line 71, in __call__
    await self.app(scope, receive, sender)
  File "C:\Users\Sayed\brickred\lcd\venv\lib\site-packages\starlette\routing.py", line 566, in __call__
    await route.handle(scope, receive, send)
  File "C:\Users\Sayed\brickred\lcd\venv\lib\site-packages\starlette\routing.py", line 227, in handle
    await self.app(scope, receive, send)
  File "C:\Users\Sayed\brickred\lcd\venv\lib\site-packages\starlette\routing.py", line 41, in app
    response = await func(request)
  File "C:\Users\Sayed\brickred\lcd\venv\lib\site-packages\fastapi\routing.py", line 188, in app
    raw_response = await run_endpoint_function(
  File "C:\Users\Sayed\brickred\lcd\venv\lib\site-packages\fastapi\routing.py", line 135, in run_endpoint_function
    return await dependant.call(**values)
  File "D:\projects\rj\p1-sms\.\app\api\v1\endpoints\admin.py", line 35, in admin_register
    validate_access_privilege(token_items,registered_by,invokers_role,invoked_endpoint)
TypeError: validate_access_privilege() takes from 1 to 2 positional arguments but 4 were given
13-02-2023 04:58:22 PM INFO [asyncio.py:62 serve()] [Started server process [6376]]
13-02-2023 04:58:22 PM INFO [on.py:26 startup()] [Waiting for application startup.]
13-02-2023 04:58:22 PM INFO [on.py:38 startup()] [Application startup complete.]
13-02-2023 05:07:35 PM INFO [asyncio.py:62 serve()] [Started server process [3408]]
13-02-2023 05:07:35 PM INFO [on.py:26 startup()] [Waiting for application startup.]
13-02-2023 05:07:35 PM INFO [on.py:38 startup()] [Application startup complete.]
13-02-2023 05:18:22 PM INFO [asyncio.py:62 serve()] [Started server process [7492]]
13-02-2023 05:18:22 PM INFO [on.py:26 startup()] [Waiting for application startup.]
13-02-2023 05:18:22 PM INFO [on.py:38 startup()] [Application startup complete.]
13-02-2023 05:18:54 PM INFO [asyncio.py:62 serve()] [Started server process [14748]]
13-02-2023 05:18:54 PM INFO [on.py:26 startup()] [Waiting for application startup.]
13-02-2023 05:18:54 PM INFO [on.py:38 startup()] [Application startup complete.]
13-02-2023 05:19:00 PM ERROR [h11_impl.py:397 run_asgi()] [Exception in ASGI application
]
Traceback (most recent call last):
  File "C:\Users\Sayed\brickred\lcd\venv\lib\site-packages\uvicorn\protocols\http\h11_impl.py", line 394, in run_asgi
    result = await app(self.scope, self.receive, self.send)
  File "C:\Users\Sayed\brickred\lcd\venv\lib\site-packages\uvicorn\middleware\proxy_headers.py", line 45, in __call__
    return await self.app(scope, receive, send)
  File "C:\Users\Sayed\brickred\lcd\venv\lib\site-packages\fastapi\applications.py", line 190, in __call__
    await super().__call__(scope, receive, send)
  File "C:\Users\Sayed\brickred\lcd\venv\lib\site-packages\starlette\applications.py", line 111, in __call__
    await self.middleware_stack(scope, receive, send)
  File "C:\Users\Sayed\brickred\lcd\venv\lib\site-packages\starlette\middleware\errors.py", line 181, in __call__
    raise exc from None
  File "C:\Users\Sayed\brickred\lcd\venv\lib\site-packages\starlette\middleware\errors.py", line 159, in __call__
    await self.app(scope, receive, _send)
  File "C:\Users\Sayed\brickred\lcd\venv\lib\site-packages\starlette\middleware\cors.py", line 86, in __call__
    await self.simple_response(scope, receive, send, request_headers=headers)
  File "C:\Users\Sayed\brickred\lcd\venv\lib\site-packages\starlette\middleware\cors.py", line 142, in simple_response
    await self.app(scope, receive, send)
  File "C:\Users\Sayed\brickred\lcd\venv\lib\site-packages\starlette\exceptions.py", line 82, in __call__
    raise exc from None
  File "C:\Users\Sayed\brickred\lcd\venv\lib\site-packages\starlette\exceptions.py", line 71, in __call__
    await self.app(scope, receive, sender)
  File "C:\Users\Sayed\brickred\lcd\venv\lib\site-packages\starlette\routing.py", line 566, in __call__
    await route.handle(scope, receive, send)
  File "C:\Users\Sayed\brickred\lcd\venv\lib\site-packages\starlette\routing.py", line 227, in handle
    await self.app(scope, receive, send)
  File "C:\Users\Sayed\brickred\lcd\venv\lib\site-packages\starlette\routing.py", line 41, in app
    response = await func(request)
  File "C:\Users\Sayed\brickred\lcd\venv\lib\site-packages\fastapi\routing.py", line 178, in app
    solved_result = await solve_dependencies(
  File "C:\Users\Sayed\brickred\lcd\venv\lib\site-packages\fastapi\dependencies\utils.py", line 552, in solve_dependencies
    solved = await run_in_threadpool(call, **sub_values)
  File "C:\Users\Sayed\brickred\lcd\venv\lib\site-packages\starlette\concurrency.py", line 34, in run_in_threadpool
    return await loop.run_in_executor(None, func, *args)
  File "C:\Users\Sayed\AppData\Local\Programs\Python\Python39\lib\concurrent\futures\thread.py", line 58, in run
    result = self.fn(*self.args, **self.kwargs)
  File "D:\projects\rj\p1-sms\.\app\utilities\common.py", line 50, in validate_access_privilege
    __check_if_access_allowed(data['data'][0], invoker_id, invoker_role)
  File "D:\projects\rj\p1-sms\.\app\utilities\common.py", line 32, in __check_if_access_allowed
    logging.eroor('Forbidden - user blocked')
AttributeError: module 'logging' has no attribute 'eroor'
13-02-2023 05:19:26 PM INFO [asyncio.py:62 serve()] [Started server process [5844]]
13-02-2023 05:19:26 PM INFO [on.py:26 startup()] [Waiting for application startup.]
13-02-2023 05:19:26 PM INFO [on.py:38 startup()] [Application startup complete.]
13-02-2023 05:19:26 PM ERROR [common.py:32 __check_if_access_allowed()] [Forbidden - user blocked]
13-02-2023 05:20:59 PM INFO [asyncio.py:62 serve()] [Started server process [13016]]
13-02-2023 05:20:59 PM INFO [on.py:26 startup()] [Waiting for application startup.]
13-02-2023 05:20:59 PM INFO [on.py:38 startup()] [Application startup complete.]
13-02-2023 05:21:00 PM ERROR [common.py:32 __check_if_access_allowed()] [Forbidden - user blocked]
13-02-2023 05:21:46 PM INFO [asyncio.py:62 serve()] [Started server process [1560]]
13-02-2023 05:21:46 PM INFO [on.py:26 startup()] [Waiting for application startup.]
13-02-2023 05:21:46 PM INFO [on.py:38 startup()] [Application startup complete.]
13-02-2023 05:21:46 PM ERROR [common.py:32 __check_if_access_allowed()] [Forbidden - user blocked]
13-02-2023 05:22:11 PM INFO [asyncio.py:62 serve()] [Started server process [4492]]
13-02-2023 05:22:11 PM INFO [on.py:26 startup()] [Waiting for application startup.]
13-02-2023 05:22:11 PM INFO [on.py:38 startup()] [Application startup complete.]
13-02-2023 05:22:11 PM ERROR [common.py:32 __check_if_access_allowed()] [Forbidden - user blocked]
13-02-2023 05:22:13 PM ERROR [common.py:32 __check_if_access_allowed()] [Forbidden - user blocked]
13-02-2023 05:27:51 PM INFO [asyncio.py:62 serve()] [Started server process [1560]]
13-02-2023 05:27:51 PM INFO [on.py:26 startup()] [Waiting for application startup.]
13-02-2023 05:27:51 PM INFO [on.py:38 startup()] [Application startup complete.]
13-02-2023 05:28:05 PM INFO [asyncio.py:62 serve()] [Started server process [13652]]
13-02-2023 05:28:05 PM INFO [on.py:26 startup()] [Waiting for application startup.]
13-02-2023 05:28:05 PM INFO [on.py:38 startup()] [Application startup complete.]
13-02-2023 05:28:10 PM INFO [admin.py:70 admin_register()] [INSERT INTO `admin` VALUES (NULL, 'e1xample@354.com', '5169548170', '$2b$12$UT3og4/ak8PHgqiBZ3woLuAjqI7tn8ORR0qtpFje0UJzwz318HdOW', '2023-02-13 17:28:10.371918', 'example@abc.com', 'active', 'admin');]
13-02-2023 05:28:10 PM ERROR [SqlClient.py:43 INSERT()] [(1062, "Duplicate entry 'e1xample@354.com' for key 'admin.email'")]
13-02-2023 05:28:10 PM ERROR [admin.py:75 admin_register()] [Admin register - '(1062, "Duplicate entry 'e1xample@354.com' for key 'admin.email'")']
13-02-2023 05:28:10 PM INFO [admin.py:78 admin_register()] [Admin register success- 'e1xample@354.com']
13-02-2023 05:29:04 PM INFO [asyncio.py:62 serve()] [Started server process [8544]]
13-02-2023 05:29:04 PM INFO [on.py:26 startup()] [Waiting for application startup.]
13-02-2023 05:29:04 PM INFO [on.py:38 startup()] [Application startup complete.]
13-02-2023 05:29:04 PM INFO [admin.py:70 admin_register()] [INSERT INTO `admin` VALUES (NULL, 'e1xample@354.com', '5169548170', '$2b$12$HbD/029DBeORf5Y4Nsk9D.T4BR6HMWNdNGZgQXBSuPMR.6pPeppdG', '2023-02-13 17:29:04.959646', 'example@abc.com', 'active', 'admin');]
13-02-2023 05:29:04 PM ERROR [SqlClient.py:43 INSERT()] [(1062, "Duplicate entry 'e1xample@354.com' for key 'admin.email'")]
13-02-2023 05:29:04 PM ERROR [admin.py:75 admin_register()] [Admin register - '(1062, "Duplicate entry 'e1xample@354.com' for key 'admin.email'")']
13-02-2023 05:29:04 PM INFO [admin.py:78 admin_register()] [Admin register success- 'e1xample@354.com']
13-02-2023 05:29:46 PM INFO [asyncio.py:62 serve()] [Started server process [11020]]
13-02-2023 05:29:46 PM INFO [on.py:26 startup()] [Waiting for application startup.]
13-02-2023 05:29:46 PM INFO [on.py:38 startup()] [Application startup complete.]
13-02-2023 05:29:48 PM ERROR [h11_impl.py:397 run_asgi()] [Exception in ASGI application
]
Traceback (most recent call last):
  File "C:\Users\Sayed\brickred\lcd\venv\lib\site-packages\uvicorn\protocols\http\h11_impl.py", line 394, in run_asgi
    result = await app(self.scope, self.receive, self.send)
  File "C:\Users\Sayed\brickred\lcd\venv\lib\site-packages\uvicorn\middleware\proxy_headers.py", line 45, in __call__
    return await self.app(scope, receive, send)
  File "C:\Users\Sayed\brickred\lcd\venv\lib\site-packages\fastapi\applications.py", line 190, in __call__
    await super().__call__(scope, receive, send)
  File "C:\Users\Sayed\brickred\lcd\venv\lib\site-packages\starlette\applications.py", line 111, in __call__
    await self.middleware_stack(scope, receive, send)
  File "C:\Users\Sayed\brickred\lcd\venv\lib\site-packages\starlette\middleware\errors.py", line 181, in __call__
    raise exc from None
  File "C:\Users\Sayed\brickred\lcd\venv\lib\site-packages\starlette\middleware\errors.py", line 159, in __call__
    await self.app(scope, receive, _send)
  File "C:\Users\Sayed\brickred\lcd\venv\lib\site-packages\starlette\middleware\cors.py", line 86, in __call__
    await self.simple_response(scope, receive, send, request_headers=headers)
  File "C:\Users\Sayed\brickred\lcd\venv\lib\site-packages\starlette\middleware\cors.py", line 142, in simple_response
    await self.app(scope, receive, send)
  File "C:\Users\Sayed\brickred\lcd\venv\lib\site-packages\starlette\exceptions.py", line 82, in __call__
    raise exc from None
  File "C:\Users\Sayed\brickred\lcd\venv\lib\site-packages\starlette\exceptions.py", line 71, in __call__
    await self.app(scope, receive, sender)
  File "C:\Users\Sayed\brickred\lcd\venv\lib\site-packages\starlette\routing.py", line 566, in __call__
    await route.handle(scope, receive, send)
  File "C:\Users\Sayed\brickred\lcd\venv\lib\site-packages\starlette\routing.py", line 227, in handle
    await self.app(scope, receive, send)
  File "C:\Users\Sayed\brickred\lcd\venv\lib\site-packages\starlette\routing.py", line 41, in app
    response = await func(request)
  File "C:\Users\Sayed\brickred\lcd\venv\lib\site-packages\fastapi\routing.py", line 178, in app
    solved_result = await solve_dependencies(
  File "C:\Users\Sayed\brickred\lcd\venv\lib\site-packages\fastapi\dependencies\utils.py", line 550, in solve_dependencies
    solved = await call(**sub_values)
  File "D:\projects\rj\p1-sms\.\app\auth\auth_bearer.py", line 61, in __call__
    self.validate_access()
TypeError: validate_access() missing 1 required positional argument: 'request'
13-02-2023 05:30:49 PM INFO [asyncio.py:62 serve()] [Started server process [14264]]
13-02-2023 05:30:49 PM INFO [on.py:26 startup()] [Waiting for application startup.]
13-02-2023 05:30:49 PM INFO [on.py:38 startup()] [Application startup complete.]
13-02-2023 05:30:56 PM ERROR [common.py:32 __check_if_access_allowed()] [Forbidden - user blocked]
13-02-2023 05:32:27 PM INFO [asyncio.py:62 serve()] [Started server process [11352]]
13-02-2023 05:32:27 PM INFO [on.py:26 startup()] [Waiting for application startup.]
13-02-2023 05:32:27 PM INFO [on.py:38 startup()] [Application startup complete.]
13-02-2023 05:32:33 PM ERROR [common.py:32 __check_if_access_allowed()] [Forbidden - user blocked]
13-02-2023 05:33:00 PM INFO [admin.py:70 admin_register()] [INSERT INTO `admin` VALUES (NULL, 'e1xample@354.com', '5169548170', '$2b$12$CRdTPt9rk1v9PoIvrLc8gu9jE3t/o5J53GdycUlANjl.vYbWnfsz.', '2023-02-13 17:33:00.708193', 'example@abc.com', 'active', 'admin');]
13-02-2023 05:33:00 PM ERROR [SqlClient.py:43 INSERT()] [(1062, "Duplicate entry 'e1xample@354.com' for key 'admin.email'")]
13-02-2023 05:33:00 PM ERROR [admin.py:75 admin_register()] [Admin register - '(1062, "Duplicate entry 'e1xample@354.com' for key 'admin.email'")']
13-02-2023 05:33:00 PM INFO [admin.py:78 admin_register()] [Admin register success- 'e1xample@354.com']
13-02-2023 05:33:14 PM INFO [asyncio.py:62 serve()] [Started server process [13328]]
13-02-2023 05:33:14 PM INFO [on.py:26 startup()] [Waiting for application startup.]
13-02-2023 05:33:14 PM INFO [on.py:38 startup()] [Application startup complete.]
13-02-2023 05:33:15 PM INFO [admin.py:70 admin_register()] [INSERT INTO `admin` VALUES (NULL, 'e1xample@354.com', '5169548170', '$2b$12$rcZ3.ULmZlq5dv/I.Wgnve.ckHL7nHOzLlLu/iSokzot6Lvu8Ogle', '2023-02-13 17:33:15.610356', 'example@abc.com', 'active', 'admin');]
13-02-2023 05:33:15 PM ERROR [SqlClient.py:43 INSERT()] [(1062, "Duplicate entry 'e1xample@354.com' for key 'admin.email'")]
13-02-2023 05:33:15 PM ERROR [admin.py:75 admin_register()] [Admin register - '(1062, "Duplicate entry 'e1xample@354.com' for key 'admin.email'")']
13-02-2023 05:33:15 PM INFO [admin.py:78 admin_register()] [Admin register success- 'e1xample@354.com']
13-02-2023 05:33:28 PM INFO [asyncio.py:62 serve()] [Started server process [3156]]
13-02-2023 05:33:28 PM INFO [on.py:26 startup()] [Waiting for application startup.]
13-02-2023 05:33:28 PM INFO [on.py:38 startup()] [Application startup complete.]
13-02-2023 05:34:33 PM ERROR [common.py:29 __check_if_access_allowed()] [endpoint disabled]
13-02-2023 05:36:56 PM INFO [asyncio.py:62 serve()] [Started server process [13552]]
13-02-2023 05:36:56 PM INFO [on.py:26 startup()] [Waiting for application startup.]
13-02-2023 05:36:56 PM INFO [on.py:38 startup()] [Application startup complete.]
13-02-2023 05:38:10 PM INFO [asyncio.py:62 serve()] [Started server process [6540]]
13-02-2023 05:38:10 PM INFO [on.py:26 startup()] [Waiting for application startup.]
13-02-2023 05:38:10 PM INFO [on.py:38 startup()] [Application startup complete.]
13-02-2023 05:38:28 PM INFO [asyncio.py:62 serve()] [Started server process [13824]]
13-02-2023 05:38:28 PM INFO [on.py:26 startup()] [Waiting for application startup.]
13-02-2023 05:38:28 PM INFO [on.py:38 startup()] [Application startup complete.]
13-02-2023 05:39:03 PM INFO [asyncio.py:62 serve()] [Started server process [1892]]
13-02-2023 05:39:03 PM INFO [on.py:26 startup()] [Waiting for application startup.]
13-02-2023 05:39:03 PM INFO [on.py:38 startup()] [Application startup complete.]
13-02-2023 05:41:01 PM INFO [asyncio.py:62 serve()] [Started server process [4848]]
13-02-2023 05:41:01 PM INFO [on.py:26 startup()] [Waiting for application startup.]
13-02-2023 05:41:01 PM INFO [on.py:38 startup()] [Application startup complete.]
13-02-2023 05:41:30 PM INFO [asyncio.py:62 serve()] [Started server process [15088]]
13-02-2023 05:41:30 PM INFO [on.py:26 startup()] [Waiting for application startup.]
13-02-2023 05:41:30 PM INFO [on.py:38 startup()] [Application startup complete.]
13-02-2023 05:42:04 PM INFO [asyncio.py:62 serve()] [Started server process [14892]]
13-02-2023 05:42:04 PM INFO [on.py:26 startup()] [Waiting for application startup.]
13-02-2023 05:42:04 PM INFO [on.py:38 startup()] [Application startup complete.]
13-02-2023 05:42:47 PM INFO [asyncio.py:62 serve()] [Started server process [14980]]
13-02-2023 05:42:47 PM INFO [on.py:26 startup()] [Waiting for application startup.]
13-02-2023 05:42:47 PM INFO [on.py:38 startup()] [Application startup complete.]
13-02-2023 05:43:08 PM INFO [asyncio.py:62 serve()] [Started server process [14532]]
13-02-2023 05:43:08 PM INFO [on.py:26 startup()] [Waiting for application startup.]
13-02-2023 05:43:08 PM INFO [on.py:38 startup()] [Application startup complete.]
13-02-2023 05:43:38 PM INFO [asyncio.py:62 serve()] [Started server process [13680]]
13-02-2023 05:43:38 PM INFO [on.py:26 startup()] [Waiting for application startup.]
13-02-2023 05:43:38 PM INFO [on.py:38 startup()] [Application startup complete.]
13-02-2023 05:43:48 PM INFO [asyncio.py:62 serve()] [Started server process [14784]]
13-02-2023 05:43:48 PM INFO [on.py:26 startup()] [Waiting for application startup.]
13-02-2023 05:43:48 PM INFO [on.py:38 startup()] [Application startup complete.]
13-02-2023 05:45:01 PM INFO [asyncio.py:62 serve()] [Started server process [14264]]
13-02-2023 05:45:01 PM INFO [on.py:26 startup()] [Waiting for application startup.]
13-02-2023 05:45:01 PM INFO [on.py:38 startup()] [Application startup complete.]
13-02-2023 05:47:25 PM INFO [asyncio.py:62 serve()] [Started server process [6504]]
13-02-2023 05:47:25 PM INFO [on.py:26 startup()] [Waiting for application startup.]
13-02-2023 05:47:25 PM INFO [on.py:38 startup()] [Application startup complete.]
13-02-2023 05:48:26 PM INFO [asyncio.py:62 serve()] [Started server process [8084]]
13-02-2023 05:48:26 PM INFO [on.py:26 startup()] [Waiting for application startup.]
13-02-2023 05:48:26 PM INFO [on.py:38 startup()] [Application startup complete.]
13-02-2023 05:48:46 PM INFO [asyncio.py:62 serve()] [Started server process [13664]]
13-02-2023 05:48:46 PM INFO [on.py:26 startup()] [Waiting for application startup.]
13-02-2023 05:48:46 PM INFO [on.py:38 startup()] [Application startup complete.]
13-02-2023 05:48:50 PM INFO [asyncio.py:62 serve()] [Started server process [2984]]
13-02-2023 05:48:50 PM INFO [on.py:26 startup()] [Waiting for application startup.]
13-02-2023 05:48:50 PM INFO [on.py:38 startup()] [Application startup complete.]
13-02-2023 05:49:18 PM INFO [settings.py:19 register_endpoints()] [INSERT INTO `ep_control_settings`(`endpoint`,`is_disabled`) VALUES ('/openapi.json,/admin/register,/admin/user/is-exist,/common/login,/settings/register-ep,/session/if-valid',0);]
13-02-2023 05:49:18 PM INFO [SqlClient.py:41 INSERT()] [Data inserted to db]
13-02-2023 05:49:18 PM INFO [settings.py:27 register_endpoints()] [Endpoint registry updated']
13-02-2023 05:49:48 PM INFO [asyncio.py:62 serve()] [Started server process [1660]]
13-02-2023 05:49:48 PM INFO [on.py:26 startup()] [Waiting for application startup.]
13-02-2023 05:49:48 PM INFO [on.py:38 startup()] [Application startup complete.]
13-02-2023 05:49:54 PM INFO [settings.py:19 register_endpoints()] [INSERT INTO `ep_control_settings`(`endpoint`,`is_disabled`) VALUES ('/openapi.json,/admin/register,/admin/user/is-exist,/common/login,/settings/register-ep,/session/if-valid');]
13-02-2023 05:49:54 PM ERROR [SqlClient.py:43 INSERT()] [(1136, "Column count doesn't match value count at row 1")]
13-02-2023 05:49:54 PM ERROR [settings.py:24 register_endpoints()] [Admin register - '(1136, "Column count doesn't match value count at row 1")']
13-02-2023 05:49:54 PM INFO [settings.py:27 register_endpoints()] [Endpoint registry updated']
13-02-2023 05:50:14 PM INFO [settings.py:19 register_endpoints()] [INSERT INTO `ep_control_settings`(`endpoint`,`is_disabled`) VALUES ('/openapi.json,/admin/register,/admin/user/is-exist,/common/login,/settings/register-ep,/session/if-valid');]
13-02-2023 05:50:14 PM ERROR [SqlClient.py:43 INSERT()] [(1136, "Column count doesn't match value count at row 1")]
13-02-2023 05:50:14 PM ERROR [settings.py:24 register_endpoints()] [Admin register - '(1136, "Column count doesn't match value count at row 1")']
13-02-2023 05:50:14 PM INFO [settings.py:27 register_endpoints()] [Endpoint registry updated']
13-02-2023 05:50:54 PM INFO [settings.py:19 register_endpoints()] [INSERT INTO `ep_control_settings`(`endpoint`,`is_disabled`) VALUES ('/openapi.json,/admin/register,/admin/user/is-exist,/common/login,/settings/register-ep,/session/if-valid');]
13-02-2023 05:50:54 PM ERROR [SqlClient.py:43 INSERT()] [(1136, "Column count doesn't match value count at row 1")]
13-02-2023 05:50:54 PM ERROR [settings.py:24 register_endpoints()] [Admin register - '(1136, "Column count doesn't match value count at row 1")']
13-02-2023 05:50:54 PM INFO [settings.py:27 register_endpoints()] [Endpoint registry updated']
13-02-2023 05:51:06 PM INFO [asyncio.py:62 serve()] [Started server process [2984]]
13-02-2023 05:51:06 PM INFO [on.py:26 startup()] [Waiting for application startup.]
13-02-2023 05:51:06 PM INFO [on.py:38 startup()] [Application startup complete.]
13-02-2023 05:51:10 PM INFO [settings.py:19 register_endpoints()] [INSERT INTO `ep_control_settings`(`endpoint`,`is_disabled`) VALUES ('/openapi.json,/admin/register,/admin/user/is-exist,/common/login,/settings/register-ep,/session/if-valid',0);]
13-02-2023 05:51:10 PM INFO [SqlClient.py:41 INSERT()] [Data inserted to db]
13-02-2023 05:51:10 PM INFO [settings.py:27 register_endpoints()] [Endpoint registry updated']
13-02-2023 05:52:55 PM INFO [asyncio.py:62 serve()] [Started server process [14264]]
13-02-2023 05:52:55 PM INFO [on.py:26 startup()] [Waiting for application startup.]
13-02-2023 05:52:55 PM INFO [on.py:38 startup()] [Application startup complete.]
13-02-2023 05:52:58 PM INFO [settings.py:22 register_endpoints()] [INSERT INTO `ep_control_settings`(`endpoint`,`is_disabled`) VALUES ('/openapi.json,/admin/register,/admin/user/is-exist,/common/login,/settings/register-ep,/session/if-valid','0');]
13-02-2023 05:52:58 PM INFO [SqlClient.py:41 INSERT()] [Data inserted to db]
13-02-2023 05:52:58 PM INFO [settings.py:30 register_endpoints()] [Endpoint registry updated']
13-02-2023 05:53:32 PM INFO [asyncio.py:62 serve()] [Started server process [14668]]
13-02-2023 05:53:32 PM INFO [on.py:26 startup()] [Waiting for application startup.]
13-02-2023 05:53:32 PM INFO [on.py:38 startup()] [Application startup complete.]
13-02-2023 05:56:07 PM INFO [asyncio.py:62 serve()] [Started server process [12576]]
13-02-2023 05:56:07 PM INFO [on.py:26 startup()] [Waiting for application startup.]
13-02-2023 05:56:07 PM INFO [on.py:38 startup()] [Application startup complete.]
13-02-2023 05:56:13 PM INFO [settings.py:22 register_endpoints()] [INSERT INTO `ep_control_settings`(`endpoint`,`is_disabled`) VALUES e1/111/ + ',' + '0' +e2/2222/ + '0';]
13-02-2023 05:56:13 PM ERROR [SqlClient.py:43 INSERT()] [(1064, "You have an error in your SQL syntax; check the manual that corresponds to your MySQL server version for the right syntax to use near 'e1/111/ + ',' + '0' +e2/2222/ + '0'' at line 1")]
13-02-2023 05:56:13 PM ERROR [settings.py:27 register_endpoints()] [Admin register - '(1064, "You have an error in your SQL syntax; check the manual that corresponds to your MySQL server version for the right syntax to use near 'e1/111/ + ',' + '0' +e2/2222/ + '0'' at line 1")']
13-02-2023 05:56:13 PM INFO [settings.py:30 register_endpoints()] [Endpoint registry updated']
13-02-2023 05:57:46 PM INFO [asyncio.py:62 serve()] [Started server process [2088]]
13-02-2023 05:57:46 PM INFO [on.py:26 startup()] [Waiting for application startup.]
13-02-2023 05:57:46 PM INFO [on.py:38 startup()] [Application startup complete.]
13-02-2023 05:57:49 PM INFO [settings.py:22 register_endpoints()] [INSERT INTO `ep_control_settings`(`endpoint`,`is_disabled`) VALUES (e1/111/,0),(e2/2222/,0);]
13-02-2023 05:57:49 PM ERROR [SqlClient.py:43 INSERT()] [(1064, "You have an error in your SQL syntax; check the manual that corresponds to your MySQL server version for the right syntax to use near ',0),(e2/2222/,0)' at line 1")]
13-02-2023 05:57:49 PM ERROR [settings.py:27 register_endpoints()] [Admin register - '(1064, "You have an error in your SQL syntax; check the manual that corresponds to your MySQL server version for the right syntax to use near ',0),(e2/2222/,0)' at line 1")']
13-02-2023 05:57:49 PM INFO [settings.py:30 register_endpoints()] [Endpoint registry updated']
13-02-2023 05:58:16 PM INFO [asyncio.py:62 serve()] [Started server process [9996]]
13-02-2023 05:58:16 PM INFO [on.py:26 startup()] [Waiting for application startup.]
13-02-2023 05:58:16 PM INFO [on.py:38 startup()] [Application startup complete.]
13-02-2023 05:58:18 PM INFO [settings.py:22 register_endpoints()] [INSERT INTO `ep_control_settings`(`endpoint`,`is_disabled`) VALUES ('e1/111/',0),('e2/2222/',0);]
13-02-2023 05:58:18 PM INFO [SqlClient.py:41 INSERT()] [Data inserted to db]
13-02-2023 05:58:18 PM INFO [settings.py:30 register_endpoints()] [Endpoint registry updated']
13-02-2023 05:59:53 PM INFO [asyncio.py:62 serve()] [Started server process [8692]]
13-02-2023 05:59:53 PM INFO [on.py:26 startup()] [Waiting for application startup.]
13-02-2023 05:59:53 PM INFO [on.py:38 startup()] [Application startup complete.]
13-02-2023 05:59:57 PM INFO [settings.py:24 register_endpoints()] [INSERT INTO `ep_control_settings`(`endpoint`,`is_disabled`) VALUES ('/openapi.json',0)('/admin/register',0)('/admin/user/is-exist',0)('/common/login',0)('/settings/register-ep',0)('/session/if-valid',0);]
13-02-2023 05:59:57 PM ERROR [SqlClient.py:43 INSERT()] [(1064, "You have an error in your SQL syntax; check the manual that corresponds to your MySQL server version for the right syntax to use near '('/admin/register',0)('/admin/user/is-exist',0)('/common/login',0)('/settings/re' at line 1")]
13-02-2023 05:59:57 PM ERROR [settings.py:29 register_endpoints()] [Admin register - '(1064, "You have an error in your SQL syntax; check the manual that corresponds to your MySQL server version for the right syntax to use near '('/admin/register',0)('/admin/user/is-exist',0)('/common/login',0)('/settings/re' at line 1")']
13-02-2023 05:59:57 PM INFO [settings.py:32 register_endpoints()] [Endpoint registry updated']
13-02-2023 06:00:54 PM INFO [asyncio.py:62 serve()] [Started server process [6904]]
13-02-2023 06:00:54 PM INFO [on.py:26 startup()] [Waiting for application startup.]
13-02-2023 06:00:54 PM INFO [on.py:38 startup()] [Application startup complete.]
13-02-2023 06:01:45 PM INFO [asyncio.py:62 serve()] [Started server process [15128]]
13-02-2023 06:01:45 PM INFO [on.py:26 startup()] [Waiting for application startup.]
13-02-2023 06:01:45 PM INFO [on.py:38 startup()] [Application startup complete.]
13-02-2023 06:02:07 PM INFO [settings.py:24 register_endpoints()] [INSERT INTO `ep_control_settings`(`endpoint`,`is_disabled`) VALUES ('/openapi.json',0),('/admin/register',0),('/admin/user/is-exist',0),('/common/login',0),('/settings/register-ep',0),('/session/if-valid',0),;]
13-02-2023 06:02:07 PM ERROR [SqlClient.py:43 INSERT()] [(1064, "You have an error in your SQL syntax; check the manual that corresponds to your MySQL server version for the right syntax to use near '' at line 1")]
13-02-2023 06:02:07 PM ERROR [settings.py:29 register_endpoints()] [Admin register - '(1064, "You have an error in your SQL syntax; check the manual that corresponds to your MySQL server version for the right syntax to use near '' at line 1")']
13-02-2023 06:02:07 PM INFO [settings.py:32 register_endpoints()] [Endpoint registry updated']
13-02-2023 06:02:27 PM INFO [asyncio.py:62 serve()] [Started server process [3896]]
13-02-2023 06:02:27 PM INFO [on.py:26 startup()] [Waiting for application startup.]
13-02-2023 06:02:27 PM INFO [on.py:38 startup()] [Application startup complete.]
13-02-2023 06:02:28 PM INFO [settings.py:24 register_endpoints()] [INSERT INTO `ep_control_settings`(`endpoint`,`is_disabled`) VALUES ('/openapi.json',0),('/admin/register',0),('/admin/user/is-exist',0),('/common/login',0),('/settings/register-ep',0),('/session/if-valid',0),;]
13-02-2023 06:02:28 PM ERROR [SqlClient.py:43 INSERT()] [(1064, "You have an error in your SQL syntax; check the manual that corresponds to your MySQL server version for the right syntax to use near '' at line 1")]
13-02-2023 06:02:28 PM ERROR [settings.py:29 register_endpoints()] [Admin register - '(1064, "You have an error in your SQL syntax; check the manual that corresponds to your MySQL server version for the right syntax to use near '' at line 1")']
13-02-2023 06:02:28 PM INFO [settings.py:32 register_endpoints()] [Endpoint registry updated']
13-02-2023 06:02:44 PM INFO [asyncio.py:62 serve()] [Started server process [12464]]
13-02-2023 06:02:44 PM INFO [on.py:26 startup()] [Waiting for application startup.]
13-02-2023 06:02:44 PM INFO [on.py:38 startup()] [Application startup complete.]
13-02-2023 06:02:49 PM INFO [asyncio.py:62 serve()] [Started server process [6904]]
13-02-2023 06:02:49 PM INFO [on.py:26 startup()] [Waiting for application startup.]
13-02-2023 06:02:49 PM INFO [on.py:38 startup()] [Application startup complete.]
13-02-2023 06:02:50 PM INFO [settings.py:24 register_endpoints()] [INSERT INTO `ep_control_settings`(`endpoint`,`is_disabled`) VALUES ('/openapi.json',0),('/admin/register',0),('/admin/user/is-exist',0),('/common/login',0),('/settings/register-ep',0),('/session/if-valid',0);]
13-02-2023 06:02:50 PM INFO [SqlClient.py:41 INSERT()] [Data inserted to db]
13-02-2023 06:02:50 PM INFO [settings.py:32 register_endpoints()] [Endpoint registry updated']
13-02-2023 06:06:56 PM INFO [asyncio.py:62 serve()] [Started server process [10284]]
13-02-2023 06:06:56 PM INFO [on.py:26 startup()] [Waiting for application startup.]
13-02-2023 06:06:56 PM INFO [on.py:38 startup()] [Application startup complete.]
13-02-2023 06:07:06 PM INFO [asyncio.py:62 serve()] [Started server process [13908]]
13-02-2023 06:07:06 PM INFO [on.py:26 startup()] [Waiting for application startup.]
13-02-2023 06:07:06 PM INFO [on.py:38 startup()] [Application startup complete.]
13-02-2023 06:07:10 PM INFO [settings.py:22 register_endpoints()] [INSERT INTO `ep_control_settings`(`endpoint`,`is_disabled`) VALUES ('/openapi.json',0),('/admin/register',0),('/admin/user/is-exist',0),('/common/login',0),('/settings/register-ep',0),('/session/if-valid',0);]
13-02-2023 06:07:10 PM INFO [SqlClient.py:41 INSERT()] [Data inserted to db]
13-02-2023 06:07:10 PM INFO [settings.py:30 register_endpoints()] [Endpoint registry updated']
13-02-2023 06:07:27 PM INFO [asyncio.py:62 serve()] [Started server process [11024]]
13-02-2023 06:07:27 PM INFO [on.py:26 startup()] [Waiting for application startup.]
13-02-2023 06:07:27 PM INFO [on.py:38 startup()] [Application startup complete.]
13-02-2023 06:08:37 PM INFO [asyncio.py:62 serve()] [Started server process [10668]]
13-02-2023 06:08:37 PM INFO [on.py:26 startup()] [Waiting for application startup.]
13-02-2023 06:08:37 PM INFO [on.py:38 startup()] [Application startup complete.]
13-02-2023 06:08:45 PM INFO [settings.py:38 register_endpoints()] [SELECT * FROM `ep_control_settings`]
13-02-2023 06:09:07 PM INFO [asyncio.py:62 serve()] [Started server process [12864]]
13-02-2023 06:09:07 PM INFO [on.py:26 startup()] [Waiting for application startup.]
13-02-2023 06:09:07 PM INFO [on.py:38 startup()] [Application startup complete.]
13-02-2023 06:09:12 PM INFO [asyncio.py:62 serve()] [Started server process [11824]]
13-02-2023 06:09:12 PM INFO [on.py:26 startup()] [Waiting for application startup.]
13-02-2023 06:09:12 PM INFO [on.py:38 startup()] [Application startup complete.]
13-02-2023 06:10:53 PM INFO [asyncio.py:62 serve()] [Started server process [15120]]
13-02-2023 06:10:53 PM INFO [on.py:26 startup()] [Waiting for application startup.]
13-02-2023 06:10:53 PM INFO [on.py:38 startup()] [Application startup complete.]
13-02-2023 06:10:56 PM INFO [settings.py:38 register_endpoints()] [SELECT * FROM `ep_control_settings`]
13-02-2023 06:13:10 PM INFO [asyncio.py:62 serve()] [Started server process [5976]]
13-02-2023 06:13:10 PM INFO [on.py:26 startup()] [Waiting for application startup.]
13-02-2023 06:13:10 PM INFO [on.py:38 startup()] [Application startup complete.]
13-02-2023 06:13:14 PM INFO [asyncio.py:62 serve()] [Started server process [15164]]
13-02-2023 06:13:14 PM INFO [on.py:26 startup()] [Waiting for application startup.]
13-02-2023 06:13:14 PM INFO [on.py:38 startup()] [Application startup complete.]
13-02-2023 06:13:22 PM INFO [settings.py:22 register_endpoints()] [INSERT INTO `ep_control_settings`(`endpoint`,`is_disabled`) VALUES ('/openapi.json',0),('/admin/register',0),('/admin/user/is-exist',0),('/common/login',0),('/settings/register-ep',0),('/settings/db-registered-ep',0),('/settings/db-registered-ep',0),('/session/if-valid',0);]
13-02-2023 06:13:22 PM INFO [SqlClient.py:41 INSERT()] [Data inserted to db]
13-02-2023 06:13:22 PM INFO [settings.py:30 register_endpoints()] [Endpoint registry updated']
13-02-2023 06:13:30 PM INFO [asyncio.py:62 serve()] [Started server process [15020]]
13-02-2023 06:13:30 PM INFO [on.py:26 startup()] [Waiting for application startup.]
13-02-2023 06:13:30 PM INFO [on.py:38 startup()] [Application startup complete.]
13-02-2023 06:14:08 PM INFO [asyncio.py:62 serve()] [Started server process [1684]]
13-02-2023 06:14:08 PM INFO [on.py:26 startup()] [Waiting for application startup.]
13-02-2023 06:14:08 PM INFO [on.py:38 startup()] [Application startup complete.]
13-02-2023 06:15:02 PM INFO [asyncio.py:62 serve()] [Started server process [11064]]
13-02-2023 06:15:02 PM INFO [on.py:26 startup()] [Waiting for application startup.]
13-02-2023 06:15:02 PM INFO [on.py:38 startup()] [Application startup complete.]
13-02-2023 06:16:05 PM INFO [asyncio.py:62 serve()] [Started server process [4452]]
13-02-2023 06:16:05 PM INFO [on.py:26 startup()] [Waiting for application startup.]
13-02-2023 06:16:05 PM INFO [on.py:38 startup()] [Application startup complete.]
13-02-2023 06:16:07 PM INFO [asyncio.py:62 serve()] [Started server process [9524]]
13-02-2023 06:16:07 PM INFO [on.py:26 startup()] [Waiting for application startup.]
13-02-2023 06:16:07 PM INFO [on.py:38 startup()] [Application startup complete.]
13-02-2023 06:16:21 PM INFO [asyncio.py:62 serve()] [Started server process [11688]]
13-02-2023 06:16:21 PM INFO [on.py:26 startup()] [Waiting for application startup.]
13-02-2023 06:16:21 PM INFO [on.py:38 startup()] [Application startup complete.]
13-02-2023 06:16:35 PM INFO [settings.py:22 register_endpoints()] [INSERT INTO `ep_control_settings`(`endpoint`,`is_disabled`) VALUES ('/openapi.json',0),('/admin/register',0),('/admin/user/is-exist',0),('/common/login',0),('/settings/register-ep',0),('/settings/db-registered-ep',0),('/settings/app-registered-ep',0),('/session/if-valid',0);]
13-02-2023 06:16:35 PM INFO [SqlClient.py:41 INSERT()] [Data inserted to db]
13-02-2023 06:16:35 PM INFO [settings.py:30 register_endpoints()] [Endpoint registry updated']
